Workbook

Sheet Recap_arc
A1: P=5 | G1: P=5 | H1: COMPLETE | J1: INCOMPLETE
A2: ALPHA | B2: COMPLETE | D2: INCOMPLETE | G2: ALPHA | H2: COMPLETE_SA | I2: COMPLETE_MA | J2: INCOMPLETE_SA | K2: INCOMPLETE_MA
B3: SIngle Allocation | C3: Multiple Allocation | D3: SIngle Allocation | E3: Multiple Allocation | G3: 0.2 | H3: 2.3691133e+13 | I3: 2.3421273e+13 | J3: 2.3691133e+13 | K3: 2.6078617e+13
A4: 0.2 | B4: =CSA!I3 -> 2.3876812 | C4: =CMA!K3 -> 2.3297101 | D4: =ICSA!K3 -> 2.6666667 | E4: =ICMA!K3 -> 2.0486111 | G4: 0.4 | H4: 2.9002563e+13 | I4: 2.8037199e+13 | J4: 2.9002563e+13 | K4: 3.2065876e+13
A5: 0.4 | B5: =CSA!I31 -> 2.365942 | C5: =CMA!K31 -> 2.2391304 | D5: =ICSA!K31 -> 3.0069444 | E5: =ICMA!K31 -> 2.2395833 | G5: 0.6 | H5: 3.3608024e+13 | I5: 3.2194e+13 | J5: 3.3608024e+13 | K5: 3.7600444e+13
A6: 0.6 | B6: 2.365942 | C6: =CMA!K59 -> 2.2101449 | D6: =ICSA!K59 -> 3.0069444 | E6: =ICMA!K59 -> 2.0364583 | G6: 0.8 | H6: 3.8185143e+13 | I6: 3.5885079e+13 | J6: 3.8185143e+13 | K6: 4.259424e+13
A7: 0.8 | B7: =CSA!I59 -> 2.3586957 | C7: =CMA!K87 -> 2.1286232 | D7: =ICSA!K87 -> 2.9722222 | E7: =ICMA!K87 -> 2.2152778 | G7: ALPHA | H7: CYCLE HUB | J7: HUB LINE
A8: ALPHA | B8: CYCLE HUB | D8: HUB LINE | H8: CYCLE HUB_SA | I8: CYCLE HUB_MA | J8: HUB LINE_SA | K8: HUB LINE_MA
B9: SIngle Allocation | C9: Multiple Allocation | D9: SIngle Allocation | E9: Multiple Allocation | G9: 0.2 | H9: 2.4318952e+13 | I9: 2.3882543e+13 | J9: 2.4318952e+13 | K9: 2.3882543e+13
A10: 0.2 | B10: =CHSA!K3 -> 3.3550725 | C10: =CHMA!K3 -> 3.0625 | D10: =HLSA!K3 -> 3.3550725 | E10: =HLMA!K3 -> 3.0625 | G10: 0.4 | H10: 3.0037217e+13 | I10: 2.9175309e+13 | J10: 30054022517292 | K10: 2.9175309e+13
A11: 0.4 | B11: =CHSA!K31 -> 2.8876812 | C11: =CHMA!K31 -> 2.8958333 | D11: =HLSA!K31 -> 3.4746377 | E11: =HLMA!K31 -> 2.8958333 | G11: 0.6 | H11: 35160004863125 | I11: 3.3413825e+13 | J11: 35185213544679 | K11: 3.3431198e+13
A12: 0.6 | B12: =CHSA!K59 -> 2.8876812 | C12: =CHMA!K58 -> 2.3541667 | D12: =HLSA!K59 -> 3.4746377 | E12: =HLMA!K59 -> 2.9010417 | G12: 0.8 | H12: 4.027898e+13 | I12: 3.6599762e+13 | J12: 4.0312592e+13 | K12: 3.6598658e+13
A13: 0.8 | B13: =CHSA!K87 -> 2.8623188 | C13: =CHMA!K86 -> 2.2604167 | D13: =HLSA!K87 -> 3.4492754 | E13: =HLMA!K87 -> 2.265625
B15: COMPLETE | D15: INCOMPLETE
B16: COMPLETE_SA | C16: COMPLETE_MA | D16: INCOMPLETE_SA | E16: INCOMPLETE_MA
B17: =AVERAGE(B4:B7) -> 2.3695652 | C17: =AVERAGE(C4:C7) -> 2.2269022 | D17: =AVERAGE(D4:D7) -> 2.9131944 | E17: =AVERAGE(E4:E7) -> 2.1349826
B18: CYCLE HUB | D18: HUB LINE
B19: CYCLE HUB_SA | C19: CYCLE HUB_MA | D19: HUB LINE_SA | E19: HUB LINE_MA
B20: =AVERAGE(B10:B13) -> 2.9981884 | C20: =AVERAGE(C10:C13) -> 2.6432292 | D20: =AVERAGE(D10:D13) -> 3.4384058 | E20: =AVERAGE(E10:E13) -> 2.78125
A35: Model | B35: Rank Fungsi Tujuan | C35: Rank Rata-rata arc Routing | D35: Rank Total Edge | E35: Average rank | F35: Final Rank
A36: COMPLETE_SA | B36: 2 | C36: 3 | D36: 4 | E36: =average(B36:D36) -> 3 | F36: 1
A37: COMPLETE_MA | B37: 1 | C37: 1 | D37: 7 | E37: =average(B37:D37) -> 3 | F37: 1
A38: INCOMPLETE_SA | B38: 2 | C38: 7 | D38: 3 | E38: =average(B38:D38) -> 4 | F38: 3
A39: INCOMPLETE_MA | B39: 8 | C39: 2 | D39: 8 | E39: =average(B39:D39) -> 6 | F39: 8
A40: CYCLE HUB_SA | B40: 6 | C40: 4 | D40: 2 | E40: =average(B40:D40) -> 4 | F40: 3
A41: CYCLE HUB_MA | B41: 4 | C41: 5 | D41: 6 | E41: =average(B41:D41) -> 5 | F41: 6
A42: HUB LINE_SA | B42: 7 | C42: 8 | D42: 1 | E42: =average(B42:D42) -> 5.3333333 | F42: 7
A43: HUB LINE_MA | B43: 4 | C43: 5 | D43: 5 | E43: =average(B43:D43) -> 4.6666667 | F43: 5

Sheet Rekap_Edge
A1: Edge Spoke to Hub | G1: Total Edge
A2: P=5 | G2: P=5
A3: ALPHA | B3: COMPLETE | D3: INCOMPLETE | G3: ALPHA | H3: COMPLETE | J3: INCOMPLETE
B4: SIngle Allocation | C4: Multiple Allocation | D4: SIngle Allocation | E4: Multiple Allocation | H4: SIngle Allocation | I4: Multiple Allocation | J4: SIngle Allocation | K4: Multiple Allocation
A5: 0.2 | B5: 19 | C5: 24 | D5: 19 | E5: 36 | G5: 0.2 | H5: =B5+B20 -> 29 | I5: =C5+C20 -> 34 | J5: =D5+D20 -> 25 | K5: =E5+E20 -> 46
A6: 0.4 | B6: 19 | C6: 28 | D6: 19 | E6: 40 | G6: 0.4 | H6: =B6+B21 -> 29 | I6: =C6+C21 -> 38 | J6: =D6+D21 -> 26 | K6: =E6+E21 -> 47
A7: 0.6 | B7: 19 | C7: 28 | D7: 19 | E7: 40 | G7: 0.6 | H7: =B7+B22 -> 29 | I7: =C7+C22 -> 38 | J7: =D7+D22 -> 25 | K7: =E7+E22 -> 50
A8: 0.8 | B8: 19 | C8: 33 | D8: 19 | E8: 44 | G8: 0.8 | H8: =B8+B23 -> 29 | I8: =C8+C23 -> 43 | J8: =D8+D23 -> 24 | K8: =E8+E23 -> 50
A9: ALPHA | B9: CYCLE HUB | D9: HUB LINE | G9: ALPHA | H9: CYCLE HUB | J9: HUB LINE
B10: SIngle Allocation | C10: Multiple Allocation | D10: SIngle Allocation | E10: Multiple Allocation | H10: SIngle Allocation | I10: Multiple Allocation | J10: SIngle Allocation | K10: Multiple Allocation
A11: 0.2 | B11: 19 | C11: 24 | D11: 19 | E11: 24 | G11: 0.2 | H11: =B11+B26 -> 24 | I11: =C11+C26 -> 29 | J11: =D11+D26 -> 23 | K11: =E11+E26 -> 28
A12: 0.4 | B12: 19 | C12: 28 | D12: 19 | E12: 28 | G12: 0.4 | H12: =B12+B27 -> 24 | I12: =C12+C27 -> 33 | J12: =D12+D27 -> 23 | K12: =E12+E27 -> 32
A13: 0.6 | B13: 19 | C13: 29 | D13: 19 | E13: 29 | G13: 0.6 | H13: =B13+B28 -> 24 | I13: =C13+C28 -> 34 | J13: =D13+D28 -> 23 | K13: =E13+E28 -> 33
A14: 0.8 | B14: 19 | C14: 39 | D14: 19 | E14: 45 | G14: 0.8 | H14: =B14+B29 -> 24 | I14: =C14+C29 -> 44 | J14: =D14+D29 -> 23 | K14: =E14+E29 -> 49
A16: Edge Hub to Hub
A17: P=5
A18: ALPHA | B18: COMPLETE | D18: INCOMPLETE
B19: SIngle Allocation | C19: Multiple Allocation | D19: SIngle Allocation | E19: Multiple Allocation
A20: 0.2 | B20: 10 | C20: 10 | D20: 6 | E20: 10
A21: 0.4 | B21: 10 | C21: 10 | D21: 7 | E21: 7
A22: 0.6 | B22: 10 | C22: 10 | D22: 6 | E22: 10
A23: 0.8 | B23: 10 | C23: 10 | D23: 5 | E23: 6
A24: ALPHA | B24: CYCLE HUB | D24: HUB LINE
B25: SIngle Allocation | C25: Multiple Allocation | D25: SIngle Allocation | E25: Multiple Allocation
A26: 0.2 | B26: 5 | C26: 5 | D26: 4 | E26: 4
A27: 0.4 | B27: 5 | C27: 5 | D27: 4 | E27: 4
A28: 0.6 | B28: 5 | C28: 5 | D28: 4 | E28: 4
A29: 0.8 | B29: 5 | C29: 5 | D29: 4 | E29: 4

Sheet CSA
A1: ALPHA 0.2
B2: 1 Edge | C2: 2 Edge | D2: 3 Edge | E2: 4 Edge | F2: 5 Edge | H2: Total Edge
A3: P1 | B3: 1 | C3: 9 | D3: 13 | G3: =sum(B3:F3) -> 23 | H3: =B3+C3*2+D3*3+E3*4+F3*5 -> 58 | I3: =sum(H3:H26)/((24*24)-24) -> 2.3876812 | J3: =sum(H3:H26) -> 1318
A4: P2 | B4: 1 | C4: 9 | D4: 13 | G4: =sum(B4:F4) -> 23 | H4: =B4+C4*2+D4*3+E4*4+F4*5 -> 58
A5: P3 | B5: 1 | C5: 9 | D5: 13 | G5: =sum(B5:F5) -> 23 | H5: =B5+C5*2+D5*3+E5*4+F5*5 -> 58
A6: P4 | B6: 1 | C6: 9 | D6: 13 | G6: =sum(B6:F6) -> 23 | H6: =B6+C6*2+D6*3+E6*4+F6*5 -> 58
A7: P5 | B7: 1 | C7: 9 | D7: 13 | G7: =sum(B7:F7) -> 23 | H7: =B7+C7*2+D7*3+E7*4+F7*5 -> 58
A8: P6 | B8: 10 | C8: 13 | G8: =sum(B8:F8) -> 23 | H8: =B8+C8*2+D8*3+E8*4+F8*5 -> 36
A9: P7 | B9: 1 | C9: 5 | D9: 17 | G9: =sum(B9:F9) -> 23 | H9: =B9+C9*2+D9*3+E9*4+F9*5 -> 62
A10: P8 | B10: 6 | C10: 17 | G10: =sum(B10:F10) -> 23 | H10: =B10+C10*2+D10*3+E10*4+F10*5 -> 40
A11: P9 | B11: 1 | C11: 5 | D11: 17 | G11: =sum(B11:F11) -> 23 | H11: =B11+C11*2+D11*3+E11*4+F11*5 -> 62
A12: P10 | B12: 1 | C12: 5 | D12: 17 | G12: =sum(B12:F12) -> 23 | H12: =B12+C12*2+D12*3+E12*4+F12*5 -> 62
A13: P11 | B13: 1 | C13: 9 | D13: 13 | G13: =sum(B13:F13) -> 23 | H13: =B13+C13*2+D13*3+E13*4+F13*5 -> 58
A14: P12 | B14: 1 | C14: 5 | D14: 17 | G14: =sum(B14:F14) -> 23 | H14: =B14+C14*2+D14*3+E14*4+F14*5 -> 62
A15: P13 | B15: 6 | C15: 17 | G15: =sum(B15:F15) -> 23 | H15: =B15+C15*2+D15*3+E15*4+F15*5 -> 40
A16: P14 | B16: 1 | C16: 6 | D16: 16 | G16: =sum(B16:F16) -> 23 | H16: =B16+C16*2+D16*3+E16*4+F16*5 -> 61
A17: P15 | B17: 7 | C17: 16 | G17: =sum(B17:F17) -> 23 | H17: =B17+C17*2+D17*3+E17*4+F17*5 -> 39
A18: P16 | B18: 1 | C18: 6 | D18: 16 | G18: =sum(B18:F18) -> 23 | H18: =B18+C18*2+D18*3+E18*4+F18*5 -> 61
A19: P17 | B19: 10 | C19: 13 | G19: =sum(B19:F19) -> 23 | H19: =B19+C19*2+D19*3+E19*4+F19*5 -> 36
A20: P18 | B20: 1 | C20: 9 | D20: 13 | G20: =sum(B20:F20) -> 23 | H20: =B20+C20*2+D20*3+E20*4+F20*5 -> 58
A21: P19 | B21: 1 | C21: 6 | D21: 16 | G21: =sum(B21:F21) -> 23 | H21: =B21+C21*2+D21*3+E21*4+F21*5 -> 61
A22: P20 | B22: 1 | C22: 9 | D22: 13 | G22: =sum(B22:F22) -> 23 | H22: =B22+C22*2+D22*3+E22*4+F22*5 -> 58
A23: P21 | B23: 1 | C23: 9 | D23: 13 | G23: =sum(B23:F23) -> 23 | H23: =B23+C23*2+D23*3+E23*4+F23*5 -> 58
A24: P22 | B24: 1 | C24: 9 | D24: 13 | G24: =sum(B24:F24) -> 23 | H24: =B24+C24*2+D24*3+E24*4+F24*5 -> 58
A25: P23 | B25: 1 | C25: 9 | D25: 13 | G25: =sum(B25:F25) -> 23 | H25: =B25+C25*2+D25*3+E25*4+F25*5 -> 58
A26: P24 | B26: 1 | C26: 9 | D26: 13 | G26: =sum(B26:F26) -> 23 | H26: =B26+C26*2+D26*3+E26*4+F26*5 -> 58
A29: ALPHA 0.4&0.6
B30: 1 Edge | C30: 2 Edge | D30: 3 Edge | E30: 4 Edge | F30: 5 Edge
A31: P1 | B31: 1 | C31: 8 | D31: 14 | G31: =sum(B31:F31) -> 23 | H31: =B31+C31*2+D31*3+E31*4+F31*5 -> 59 | I31: =sum(H31:H54)/((24*24)-24) -> 2.365942
A32: P2 | B32: 1 | C32: 8 | D32: 14 | G32: =sum(B32:F32) -> 23 | H32: =B32+C32*2+D32*3+E32*4+F32*5 -> 59
A33: P3 | B33: 1 | C33: 8 | D33: 14 | G33: =sum(B33:F33) -> 23 | H33: =B33+C33*2+D33*3+E33*4+F33*5 -> 59
A34: P4 | B34: 1 | C34: 8 | D34: 14 | G34: =sum(B34:F34) -> 23 | H34: =B34+C34*2+D34*3+E34*4+F34*5 -> 59
A35: P5 | B35: 1 | C35: 8 | D35: 14 | G35: =sum(B35:F35) -> 23 | H35: =B35+C35*2+D35*3+E35*4+F35*5 -> 59
A36: P6 | B36: 9 | C36: 14 | G36: =sum(B36:F36) -> 23 | H36: =B36+C36*2+D36*3+E36*4+F36*5 -> 37
A37: P7 | B37: 1 | C37: 5 | D37: 17 | G37: =sum(B37:F37) -> 23 | H37: =B37+C37*2+D37*3+E37*4+F37*5 -> 62
A38: P8 | B38: 6 | C38: 17 | G38: =sum(B38:F38) -> 23 | H38: =B38+C38*2+D38*3+E38*4+F38*5 -> 40
A39: P9 | B39: 1 | C39: 5 | D39: 17 | G39: =sum(B39:F39) -> 23 | H39: =B39+C39*2+D39*3+E39*4+F39*5 -> 62
A40: P10 | B40: 1 | C40: 5 | D40: 17 | G40: =sum(B40:F40) -> 23 | H40: =B40+C40*2+D40*3+E40*4+F40*5 -> 62
A41: P11 | B41: 1 | C41: 5 | D41: 17 | G41: =sum(B41:F41) -> 23 | H41: =B41+C41*2+D41*3+E41*4+F41*5 -> 62
A42: P12 | B42: 6 | C42: 17 | G42: =sum(B42:F42) -> 23 | H42: =B42+C42*2+D42*3+E42*4+F42*5 -> 40
...

Sheet CMA
A1: ALPHA 0.2
C2: 1 Edge | D2: 2 Edge | E2: 3 Edge | F2: 4 Edge | G2: 5 Edge | H2: 6 Edge | I2: 7 Edge
A3: =sum(C3:I3) -> 23 | B3: P1 | C3: 1 | D3: 9 | E3: 13 | J3: =C3+D3*2+E3*3+F3*4+G3*5+H3*6+I3*7 -> 58 | K3: =sum(J3:J26)/((24*24)-24) -> 2.3297101 | L3: =sum(J3:J26) -> 1286
A4: =sum(C4:I4) -> 23 | B4: P2 | C4: 1 | D4: 9 | E4: 13 | J4: =C4+D4*2+E4*3+F4*4+G4*5+H4*6+I4*7 -> 58
A5: =sum(C5:I5) -> 23 | B5: P3 | C5: 1 | D5: 9 | E5: 13 | J5: =C5+D5*2+E5*3+F5*4+G5*5+H5*6+I5*7 -> 58
A6: =sum(C6:I6) -> 23 | B6: P4 | C6: 1 | D6: 9 | E6: 13 | J6: =C6+D6*2+E6*3+F6*4+G6*5+H6*6+I6*7 -> 58
A7: =sum(C7:I7) -> 23 | B7: P5 | C7: 1 | D7: 9 | E7: 13 | J7: =C7+D7*2+E7*3+F7*4+G7*5+H7*6+I7*7 -> 58
A8: =sum(C8:I8) -> 23 | B8: P6 | C8: 10 | D8: 13 | J8: =C8+D8*2+E8*3+F8*4+G8*5+H8*6+I8*7 -> 36
A9: =sum(C9:I9) -> 23 | B9: P7 | C9: 1 | D9: 6 | E9: 16 | J9: =C9+D9*2+E9*3+F9*4+G9*5+H9*6+I9*7 -> 61
A10: =sum(C10:I10) -> 23 | B10: P8 | C10: 7 | D10: 16 | J10: =C10+D10*2+E10*3+F10*4+G10*5+H10*6+I10*7 -> 39
A11: =sum(C11:I11) -> 23 | B11: P9 | C11: 1 | D11: 6 | E11: 16 | J11: =C11+D11*2+E11*3+F11*4+G11*5+H11*6+I11*7 -> 61
A12: =sum(C12:I12) -> 23 | B12: P10 | C12: 2 | D12: 8 | E12: 13 | J12: =C12+D12*2+E12*3+F12*4+G12*5+H12*6+I12*7 -> 57
A13: =sum(C13:I13) -> 23 | B13: P11 | C13: 1 | D13: 9 | E13: 13 | J13: =C13+D13*2+E13*3+F13*4+G13*5+H13*6+I13*7 -> 58
A14: =sum(C14:I14) -> 23 | B14: P12 | C14: 1 | D14: 7 | E14: 15 | J14: =C14+D14*2+E14*3+F14*4+G14*5+H14*6+I14*7 -> 60
A15: =sum(C15:I15) -> 23 | B15: P13 | C15: 8 | D15: 15 | J15: =C15+D15*2+E15*3+F15*4+G15*5+H15*6+I15*7 -> 38
A16: =sum(C16:I16) -> 23 | B16: P14 | C16: 1 | D16: 7 | E16: 15 | J16: =C16+D16*2+E16*3+F16*4+G16*5+H16*6+I16*7 -> 60
A17: =sum(C17:I17) -> 23 | B17: P15 | C17: 8 | D17: 15 | J17: =C17+D17*2+E17*3+F17*4+G17*5+H17*6+I17*7 -> 38
A18: =sum(C18:I18) -> 23 | B18: P16 | C18: 1 | D18: 7 | E18: 15 | J18: =C18+D18*2+E18*3+F18*4+G18*5+H18*6+I18*7 -> 60
A19: =sum(C19:I19) -> 23 | B19: P17 | C19: 2 | D19: 9 | E19: 12 | J19: =C19+D19*2+E19*3+F19*4+G19*5+H19*6+I19*7 -> 56
A20: =sum(C20:I20) -> 23 | B20: P18 | C20: 2 | D20: 11 | E20: 10 | J20: =C20+D20*2+E20*3+F20*4+G20*5+H20*6+I20*7 -> 54
A21: =sum(C21:I21) -> 23 | B21: P19 | C21: 1 | D21: 9 | E21: 13 | J21: =C21+D21*2+E21*3+F21*4+G21*5+H21*6+I21*7 -> 58
A22: =sum(C22:I22) -> 23 | B22: P20 | C22: 3 | D22: 13 | E22: 7 | J22: =C22+D22*2+E22*3+F22*4+G22*5+H22*6+I22*7 -> 50
A23: =sum(C23:I23) -> 23 | B23: P21 | C23: 10 | D23: 13 | J23: =C23+D23*2+E23*3+F23*4+G23*5+H23*6+I23*7 -> 36
A24: =sum(C24:I24) -> 23 | B24: P22 | C24: 1 | D24: 9 | E24: 13 | J24: =C24+D24*2+E24*3+F24*4+G24*5+H24*6+I24*7 -> 58
A25: =sum(C25:I25) -> 23 | B25: P23 | C25: 1 | D25: 9 | E25: 13 | J25: =C25+D25*2+E25*3+F25*4+G25*5+H25*6+I25*7 -> 58
A26: =sum(C26:I26) -> 23 | B26: P24 | C26: 1 | D26: 9 | E26: 13 | J26: =C26+D26*2+E26*3+F26*4+G26*5+H26*6+I26*7 -> 58
A29: ALPHA 0.4
C30: 1 Edge | D30: 2 Edge | E30: 3 Edge | F30: 4 Edge | G30: 5 Edge | H30: 6 Edge | I30: 7 Edge
A31: =sum(C31:I31) -> 23 | B31: P1 | C31: 1 | D31: 9 | E31: 13 | J31: =C31+D31*2+E31*3+F31*4+G31*5+H31*6+I31*7 -> 58 | K31: =sum(J31:J54)/((24*24)-24) -> 2.2391304
A32: =sum(C32:I32) -> 23 | B32: P2 | C32: 1 | D32: 9 | E32: 13 | J32: =C32+D32*2+E32*3+F32*4+G32*5+H32*6+I32*7 -> 58
A33: =sum(C33:I33) -> 23 | B33: P3 | C33: 1 | D33: 9 | E33: 13 | J33: =C33+D33*2+E33*3+F33*4+G33*5+H33*6+I33*7 -> 58
A34: =sum(C34:I34) -> 23 | B34: P4 | C34: 1 | D34: 9 | E34: 13 | J34: =C34+D34*2+E34*3+F34*4+G34*5+H34*6+I34*7 -> 58
A35: =sum(C35:I35) -> 23 | B35: P5 | C35: 1 | D35: 9 | E35: 13 | J35: =C35+D35*2+E35*3+F35*4+G35*5+H35*6+I35*7 -> 58
A36: =sum(C36:I36) -> 23 | B36: P6 | C36: 10 | D36: 13 | J36: =C36+D36*2+E36*3+F36*4+G36*5+H36*6+I36*7 -> 36
A37: =sum(C37:I37) -> 23 | B37: P7 | C37: 2 | D37: 11 | E37: 10 | J37: =C37+D37*2+E37*3+F37*4+G37*5+H37*6+I37*7 -> 54
A38: =sum(C38:I38) -> 23 | B38: P8 | C38: 7 | D38: 16 | J38: =C38+D38*2+E38*3+F38*4+G38*5+H38*6+I38*7 -> 39
A39: =sum(C39:I39) -> 23 | B39: P9 | C39: 2 | D39: 8 | E39: 13 | J39: =C39+D39*2+E39*3+F39*4+G39*5+H39*6+I39*7 -> 57
A40: =sum(C40:I40) -> 23 | B40: P10 | C40: 2 | D40: 8 | E40: 13 | J40: =C40+D40*2+E40*3+F40*4+G40*5+H40*6+I40*7 -> 57
A41: =sum(C41:I41) -> 23 | B41: P11 | C41: 2 | D41: 10 | E41: 11 | J41: =C41+D41*2+E41*3+F41*4+G41*5+H41*6+I41*7 -> 55
A42: =sum(C42:I42) -> 23 | B42: P12 | C42: 8 | D42: 15 | J42: =C42+D42*2+E42*3+F42*4+G42*5+H42*6+I42*7 -> 38
...

Sheet ICSA
A1: ALPHA 0.2
B2: 1 Edge | C2: 2 Edge | D2: 3 Edge | E2: 4 Edge | F2: 5 Edge | G2: 6 Edge | H2: 7 Edge
A3: P1 | B3: 1 | C3: 7 | D3: 6 | E3: 9 | I3: =sum(B3:H3) -> 23 | J3: =B3+C3*2+D3*3+E3*4+F3*5+G3*6+H3*7 -> 69 | K3: =sum(J3:J26)/(24*24) -> 2.6666667
A4: P2 | B4: 1 | C4: 7 | D4: 6 | E4: 9 | I4: =sum(B4:H4) -> 23 | J4: =B4+C4*2+D4*3+E4*4+F4*5+G4*6+H4*7 -> 69
A5: P3 | B5: 1 | C5: 7 | D5: 6 | E5: 9 | I5: =sum(B5:H5) -> 23 | J5: =B5+C5*2+D5*3+E5*4+F5*5+G5*6+H5*7 -> 69
A6: P4 | B6: 1 | C6: 7 | D6: 6 | E6: 9 | I6: =sum(B6:H6) -> 23 | J6: =B6+C6*2+D6*3+E6*4+F6*5+G6*6+H6*7 -> 69
A7: P5 | B7: 1 | C7: 7 | D7: 6 | E7: 9 | I7: =sum(B7:H7) -> 23 | J7: =B7+C7*2+D7*3+E7*4+F7*5+G7*6+H7*7 -> 69
A8: P6 | B8: 8 | C8: 6 | D8: 9 | I8: =sum(B8:H8) -> 23 | J8: =B8+C8*2+D8*3+E8*4+F8*5+G8*6+H8*7 -> 47
A9: P7 | B9: 1 | C9: 3 | D9: 10 | E9: 9 | I9: =sum(B9:H9) -> 23 | J9: =B9+C9*2+D9*3+E9*4+F9*5+G9*6+H9*7 -> 73
A10: P8 | B10: 4 | C10: 9 | D10: 9 | I10: =sum(B10:H10) -> 22 | J10: =B10+C10*2+D10*3+E10*4+F10*5+G10*6+H10*7 -> 49
A11: P9 | B11: 1 | C11: 3 | D11: 10 | E11: 9 | I11: =sum(B11:H11) -> 23 | J11: =B11+C11*2+D11*3+E11*4+F11*5+G11*6+H11*7 -> 73
A12: P10 | B12: 1 | C12: 5 | D12: 17 | I12: =sum(B12:H12) -> 23 | J12: =B12+C12*2+D12*3+E12*4+F12*5+G12*6+H12*7 -> 62
A13: P11 | B13: 1 | C13: 7 | D13: 6 | E13: 9 | I13: =sum(B13:H13) -> 23 | J13: =B13+C13*2+D13*3+E13*4+F13*5+G13*6+H13*7 -> 69
A14: P12 | B14: 1 | C14: 5 | D14: 17 | I14: =sum(B14:H14) -> 23 | J14: =B14+C14*2+D14*3+E14*4+F14*5+G14*6+H14*7 -> 62
A15: P13 | B15: 6 | C15: 17 | I15: =sum(B15:H15) -> 23 | J15: =B15+C15*2+D15*3+E15*4+F15*5+G15*6+H15*7 -> 40
A16: P14 | B16: 1 | C16: 4 | D16: 10 | E16: 8 | I16: =sum(B16:H16) -> 23 | J16: =B16+C16*2+D16*3+E16*4+F16*5+G16*6+H16*7 -> 71
A17: P15 | B17: 5 | C17: 10 | D17: 8 | I17: =sum(B17:H17) -> 23 | J17: =B17+C17*2+D17*3+E17*4+F17*5+G17*6+H17*7 -> 49
A18: P16 | B18: 1 | C18: 4 | D18: 10 | E18: 8 | I18: =sum(B18:H18) -> 23 | J18: =B18+C18*2+D18*3+E18*4+F18*5+G18*6+H18*7 -> 71
A19: P17 | B19: 8 | C19: 7 | D19: 8 | I19: =sum(B19:H19) -> 23 | J19: =B19+C19*2+D19*3+E19*4+F19*5+G19*6+H19*7 -> 46
A20: P18 | B20: 1 | C20: 7 | D20: 7 | E20: 8 | I20: =sum(B20:H20) -> 23 | J20: =B20+C20*2+D20*3+E20*4+F20*5+G20*6+H20*7 -> 68
A21: P19 | B21: 1 | C21: 4 | D21: 10 | E21: 8 | I21: =sum(B21:H21) -> 23 | J21: =B21+C21*2+D21*3+E21*4+F21*5+G21*6+H21*7 -> 71
A22: P20 | B22: 1 | C22: 7 | D22: 7 | E22: 8 | I22: =sum(B22:H22) -> 23 | J22: =B22+C22*2+D22*3+E22*4+F22*5+G22*6+H22*7 -> 68
A23: P21 | B23: 1 | C23: 7 | D23: 7 | E23: 8 | I23: =sum(B23:H23) -> 23 | J23: =B23+C23*2+D23*3+E23*4+F23*5+G23*6+H23*7 -> 68
A24: P22 | B24: 1 | C24: 7 | D24: 7 | E24: 8 | I24: =sum(B24:H24) -> 23 | J24: =B24+C24*2+D24*3+E24*4+F24*5+G24*6+H24*7 -> 68
A25: P23 | B25: 1 | C25: 7 | D25: 7 | E25: 8 | I25: =sum(B25:H25) -> 23 | J25: =B25+C25*2+D25*3+E25*4+F25*5+G25*6+H25*7 -> 68
A26: P24 | B26: 1 | C26: 7 | D26: 7 | E26: 8 | I26: =sum(B26:H26) -> 23 | J26: =B26+C26*2+D26*3+E26*4+F26*5+G26*6+H26*7 -> 68
A29: ALPHA 0.4
B30: 1 Edge | C30: 2 Edge | D30: 3 Edge | E30: 4 Edge | F30: 5 Edge | G30: 6 Edge | H30: 7 Edge
A31: P1 | B31: 1 | C31: 6 | D31: 6 | E31: 2 | F31: 8 | I31: =sum(B31:H31) -> 23 | J31: =B31+C31*2+D31*3+E31*4+F31*5+G31*6+H31*7 -> 79 | K31: =sum(J31:J54)/(24*24) -> 3.0069444
A32: P2 | B32: 1 | C32: 6 | D32: 6 | E32: 2 | F32: 8 | I32: =sum(B32:H32) -> 23 | J32: =B32+C32*2+D32*3+E32*4+F32*5+G32*6+H32*7 -> 79
A33: P3 | B33: 1 | C33: 6 | D33: 6 | E33: 2 | F33: 8 | I33: =sum(B33:H33) -> 23 | J33: =B33+C33*2+D33*3+E33*4+F33*5+G33*6+H33*7 -> 79
A34: P4 | B34: 1 | C34: 6 | D34: 6 | E34: 2 | F34: 8 | I34: =sum(B34:H34) -> 23 | J34: =B34+C34*2+D34*3+E34*4+F34*5+G34*6+H34*7 -> 79
A35: P5 | B35: 1 | C35: 6 | D35: 6 | E35: 2 | F35: 8 | I35: =sum(B35:H35) -> 23 | J35: =B35+C35*2+D35*3+E35*4+F35*5+G35*6+H35*7 -> 79
A36: P6 | B36: 7 | C36: 6 | D36: 2 | E36: 8 | I36: =sum(B36:H36) -> 23 | J36: =B36+C36*2+D36*3+E36*4+F36*5+G36*6+H36*7 -> 57
A37: P7 | B37: 1 | C37: 3 | D37: 8 | E37: 3 | F37: 8 | I37: =sum(B37:H37) -> 23 | J37: =B37+C37*2+D37*3+E37*4+F37*5+G37*6+H37*7 -> 83
A38: P8 | B38: 4 | C38: 8 | D38: 3 | E38: 8 | I38: =sum(B38:H38) -> 23 | J38: =B38+C38*2+D38*3+E38*4+F38*5+G38*6+H38*7 -> 61
A39: P9 | B39: 1 | C39: 3 | D39: 8 | E39: 3 | F39: 8 | I39: =sum(B39:H39) -> 23 | J39: =B39+C39*2+D39*3+E39*4+F39*5+G39*6+H39*7 -> 83
A40: P10 | B40: 1 | C40: 4 | D40: 10 | E40: 8 | I40: =sum(B40:H40) -> 23 | J40: =B40+C40*2+D40*3+E40*4+F40*5+G40*6+H40*7 -> 71
A41: P11 | B41: 1 | C41: 4 | D41: 10 | E41: 8 | I41: =sum(B41:H41) -> 23 | J41: =B41+C41*2+D41*3+E41*4+F41*5+G41*6+H41*7 -> 71
A42: P12 | B42: 5 | C42: 10 | D42: 8 | I42: =sum(B42:H42) -> 23 | J42: =B42+C42*2+D42*3+E42*4+F42*5+G42*6+H42*7 -> 49
...

Sheet ICMA
A1: ALPHA 0.2
B2: 1 Edge | C2: 2 Edge | D2: 3 Edge | E2: 4 Edge | F2: 5 Edge | G2: 6 Edge | H2: 7 Edge
A3: P1 | B3: 2 | C3: 11 | D3: 10 | I3: =sum(B3:H3) -> 23 | J3: =B3+C3*2+D3*3+E3*4+F3*5+G3*6+H3*7 -> 54 | K3: =sum(J3:J26)/(24*24) -> 2.0486111
A4: P2 | B4: 2 | C4: 11 | D4: 10 | I4: =sum(B4:H4) -> 23 | J4: =B4+C4*2+D4*3+E4*4+F4*5+G4*6+H4*7 -> 54
A5: P3 | B5: 2 | C5: 11 | D5: 10 | I5: =sum(B5:H5) -> 23 | J5: =B5+C5*2+D5*3+E5*4+F5*5+G5*6+H5*7 -> 54
A6: P4 | B6: 2 | C6: 11 | D6: 10 | I6: =sum(B6:H6) -> 23 | J6: =B6+C6*2+D6*3+E6*4+F6*5+G6*6+H6*7 -> 54
A7: P5 | B7: 11 | C7: 12 | I7: =sum(B7:H7) -> 23 | J7: =B7+C7*2+D7*3+E7*4+F7*5+G7*6+H7*7 -> 35
A8: P6 | B8: 2 | C8: 11 | D8: 10 | I8: =sum(B8:H8) -> 23 | J8: =B8+C8*2+D8*3+E8*4+F8*5+G8*6+H8*7 -> 54
A9: P7 | B9: 2 | C9: 11 | D9: 10 | I9: =sum(B9:H9) -> 23 | J9: =B9+C9*2+D9*3+E9*4+F9*5+G9*6+H9*7 -> 54
A10: P8 | B10: 12 | C10: 11 | I10: =sum(B10:H10) -> 23 | J10: =B10+C10*2+D10*3+E10*4+F10*5+G10*6+H10*7 -> 34
A11: P9 | B11: 2 | C11: 12 | D11: 9 | I11: =sum(B11:H11) -> 23 | J11: =B11+C11*2+D11*3+E11*4+F11*5+G11*6+H11*7 -> 53
A12: P10 | B12: 2 | C12: 12 | D12: 9 | I12: =sum(B12:H12) -> 23 | J12: =B12+C12*2+D12*3+E12*4+F12*5+G12*6+H12*7 -> 53
A13: P11 | B13: 2 | C13: 13 | D13: 8 | I13: =sum(B13:H13) -> 23 | J13: =B13+C13*2+D13*3+E13*4+F13*5+G13*6+H13*7 -> 52
A14: P12 | B14: 9 | C14: 14 | I14: =sum(B14:H14) -> 23 | J14: =B14+C14*2+D14*3+E14*4+F14*5+G14*6+H14*7 -> 37
A15: P13 | B15: 2 | C15: 15 | D15: 6 | I15: =sum(B15:H15) -> 23 | J15: =B15+C15*2+D15*3+E15*4+F15*5+G15*6+H15*7 -> 50
A16: P14 | B16: 13 | C16: 10 | I16: =sum(B16:H16) -> 23 | J16: =B16+C16*2+D16*3+E16*4+F16*5+G16*6+H16*7 -> 33
A17: P15 | B17: 1 | C17: 13 | D17: 9 | I17: =sum(B17:H17) -> 23 | J17: =B17+C17*2+D17*3+E17*4+F17*5+G17*6+H17*7 -> 54
A18: P16 | B18: 1 | C18: 13 | D18: 9 | I18: =sum(B18:H18) -> 23 | J18: =B18+C18*2+D18*3+E18*4+F18*5+G18*6+H18*7 -> 54
A19: P17 | B19: 2 | C19: 13 | D19: 8 | I19: =sum(B19:H19) -> 23 | J19: =B19+C19*2+D19*3+E19*4+F19*5+G19*6+H19*7 -> 52
A20: P18 | B20: 2 | C20: 13 | D20: 8 | I20: =sum(B20:H20) -> 23 | J20: =B20+C20*2+D20*3+E20*4+F20*5+G20*6+H20*7 -> 52
A21: P19 | B21: 2 | C21: 13 | D21: 8 | I21: =sum(B21:H21) -> 23 | J21: =B21+C21*2+D21*3+E21*4+F21*5+G21*6+H21*7 -> 52
A22: P20 | B22: 2 | C22: 13 | D22: 8 | I22: =sum(B22:H22) -> 23 | J22: =B22+C22*2+D22*3+E22*4+F22*5+G22*6+H22*7 -> 52
A23: P21 | B23: 10 | C23: 12 | D23: 1 | I23: =sum(B23:H23) -> 23 | J23: =B23+C23*2+D23*3+E23*4+F23*5+G23*6+H23*7 -> 37
A24: P22 | B24: 2 | C24: 13 | D24: 8 | I24: =sum(B24:H24) -> 23 | J24: =B24+C24*2+D24*3+E24*4+F24*5+G24*6+H24*7 -> 52
A25: P23 | B25: 2 | C25: 13 | D25: 8 | I25: =sum(B25:H25) -> 23 | J25: =B25+C25*2+D25*3+E25*4+F25*5+G25*6+H25*7 -> 52
A26: P24 | B26: 2 | C26: 13 | D26: 8 | I26: =sum(B26:H26) -> 23 | J26: =B26+C26*2+D26*3+E26*4+F26*5+G26*6+H26*7 -> 52
A29: ALPHA 0.4
B30: 1 Edge | C30: 2 Edge | D30: 3 Edge | E30: 4 Edge | F30: 5 Edge | G30: 6 Edge | H30: 7 Edge
A31: P1 | B31: 2 | C31: 10 | D31: 2 | E31: 10 | I31: =sum(B31:H31) -> 24 | J31: =B31+C31*2+D31*3+E31*4+F31*5+G31*6+H31*7 -> 68 | K31: =sum(J31:J54)/(24*24) -> 2.2395833
A32: P2 | B32: 2 | C32: 10 | D32: 2 | E32: 10 | I32: =sum(B32:H32) -> 24 | J32: =B32+C32*2+D32*3+E32*4+F32*5+G32*6+H32*7 -> 68
A33: P3 | B33: 2 | C33: 10 | D33: 2 | E33: 10 | I33: =sum(B33:H33) -> 24 | J33: =B33+C33*2+D33*3+E33*4+F33*5+G33*6+H33*7 -> 68
A34: P4 | B34: 2 | C34: 10 | D34: 2 | E34: 10 | I34: =sum(B34:H34) -> 24 | J34: =B34+C34*2+D34*3+E34*4+F34*5+G34*6+H34*7 -> 68
A35: P5 | B35: 9 | C35: 4 | D35: 10 | I35: =sum(B35:H35) -> 23 | J35: =B35+C35*2+D35*3+E35*4+F35*5+G35*6+H35*7 -> 47
A36: P6 | B36: 2 | C36: 10 | D36: 2 | E36: 10 | I36: =sum(B36:H36) -> 24 | J36: =B36+C36*2+D36*3+E36*4+F36*5+G36*6+H36*7 -> 68
A37: P7 | B37: 2 | C37: 10 | D37: 2 | E37: 10 | I37: =sum(B37:H37) -> 24 | J37: =B37+C37*2+D37*3+E37*4+F37*5+G37*6+H37*7 -> 68
A38: P8 | B38: 12 | C38: 11 | I38: =sum(B38:H38) -> 23 | J38: =B38+C38*2+D38*3+E38*4+F38*5+G38*6+H38*7 -> 34
A39: P9 | B39: 2 | C39: 11 | D39: 10 | I39: =sum(B39:H39) -> 23 | J39: =B39+C39*2+D39*3+E39*4+F39*5+G39*6+H39*7 -> 54
A40: P10 | B40: 3 | C40: 20 | I40: =sum(B40:H40) -> 23 | J40: =B40+C40*2+D40*3+E40*4+F40*5+G40*6+H40*7 -> 43
A41: P11 | B41: 3 | C41: 10 | D41: 10 | I41: =sum(B41:H41) -> 23 | J41: =B41+C41*2+D41*3+E41*4+F41*5+G41*6+H41*7 -> 53
A42: P12 | B42: 7 | C42: 16 | I42: =sum(B42:H42) -> 23 | J42: =B42+C42*2+D42*3+E42*4+F42*5+G42*6+H42*7 -> 39
...

Sheet CHSA
A1: Alpha 0.2
B2: 1 Edge | C2: 2 Edge | D2: 3 Edge | E2: 4 Edge | F2: 5 Edge | G2: 6 Edge | H2: 7 Edge
A3: P1 | B3: 1 | C3: 6 | D3: 3 | E3: 5 | F3: 4 | G3: 4 | I3: =sum(B3:H3) -> 23 | J3: =B3+C3*2+D3*3+E3*4+F3*5+G3*6+H3*7 -> 86 | K3: =sum(J3:J26)/((24*24)-24) -> 3.3550725
A4: P2 | B4: 1 | C4: 6 | D4: 3 | E4: 5 | F4: 4 | G4: 4 | I4: =sum(B4:H4) -> 23 | J4: =B4+C4*2+D4*3+E4*4+F4*5+G4*6+H4*7 -> 86
A5: P3 | B5: 1 | C5: 6 | D5: 3 | E5: 5 | F5: 4 | G5: 4 | I5: =sum(B5:H5) -> 23 | J5: =B5+C5*2+D5*3+E5*4+F5*5+G5*6+H5*7 -> 86
A6: P4 | B6: 1 | C6: 6 | D6: 3 | E6: 5 | F6: 4 | G6: 4 | I6: =sum(B6:H6) -> 23 | J6: =B6+C6*2+D6*3+E6*4+F6*5+G6*6+H6*7 -> 86
A7: P5 | B7: 1 | C7: 6 | D7: 3 | E7: 5 | F7: 4 | G7: 4 | I7: =sum(B7:H7) -> 23 | J7: =B7+C7*2+D7*3+E7*4+F7*5+G7*6+H7*7 -> 86
A8: P6 | B8: 7 | C8: 3 | D8: 5 | E8: 4 | F8: 4 | I8: =sum(B8:H8) -> 23 | J8: =B8+C8*2+D8*3+E8*4+F8*5+G8*6+H8*7 -> 64
A9: P7 | B9: 1 | C9: 3 | D9: 11 | E9: 4 | F9: 4 | I9: =sum(B9:H9) -> 23 | J9: =B9+C9*2+D9*3+E9*4+F9*5+G9*6+H9*7 -> 76
A10: P8 | B10: 4 | C10: 11 | D10: 4 | E10: 4 | I10: =sum(B10:H10) -> 23 | J10: =B10+C10*2+D10*3+E10*4+F10*5+G10*6+H10*7 -> 54
A11: P9 | B11: 1 | C11: 3 | D11: 11 | E11: 4 | F11: 4 | I11: =sum(B11:H11) -> 23 | J11: =B11+C11*2+D11*3+E11*4+F11*5+G11*6+H11*7 -> 76
A12: P10 | B12: 1 | C12: 5 | D12: 7 | E12: 10 | I12: =sum(B12:H12) -> 23 | J12: =B12+C12*2+D12*3+E12*4+F12*5+G12*6+H12*7 -> 72
A13: P11 | B13: 1 | C13: 6 | D13: 3 | E13: 5 | F13: 4 | G13: 4 | I13: =sum(B13:H13) -> 23 | J13: =B13+C13*2+D13*3+E13*4+F13*5+G13*6+H13*7 -> 86
A14: P12 | B14: 1 | C14: 5 | D14: 7 | E14: 10 | I14: =sum(B14:H14) -> 23 | J14: =B14+C14*2+D14*3+E14*4+F14*5+G14*6+H14*7 -> 72
A15: P13 | B15: 6 | C15: 7 | D15: 10 | I15: =sum(B15:H15) -> 23 | J15: =B15+C15*2+D15*3+E15*4+F15*5+G15*6+H15*7 -> 50
A16: P14 | B16: 1 | C16: 4 | D16: 9 | E16: 3 | F16: 6 | I16: =sum(B16:H16) -> 23 | J16: =B16+C16*2+D16*3+E16*4+F16*5+G16*6+H16*7 -> 78
A17: P15 | B17: 5 | C17: 9 | D17: 3 | E17: 6 | I17: =sum(B17:H17) -> 23 | J17: =B17+C17*2+D17*3+E17*4+F17*5+G17*6+H17*7 -> 56
A18: P16 | B18: 1 | C18: 4 | D18: 9 | E18: 3 | F18: 6 | I18: =sum(B18:H18) -> 23 | J18: =B18+C18*2+D18*3+E18*4+F18*5+G18*6+H18*7 -> 78
A19: P17 | B19: 1 | C19: 5 | D19: 7 | E19: 10 | I19: =sum(B19:H19) -> 23 | J19: =B19+C19*2+D19*3+E19*4+F19*5+G19*6+H19*7 -> 72
A20: P18 | B20: 1 | C20: 4 | D20: 9 | E20: 3 | F20: 6 | I20: =sum(B20:H20) -> 23 | J20: =B20+C20*2+D20*3+E20*4+F20*5+G20*6+H20*7 -> 78
A21: P19 | B21: 1 | C21: 4 | D21: 4 | E21: 5 | F21: 3 | G21: 6 | I21: =sum(B21:H21) -> 23 | J21: =B21+C21*2+D21*3+E21*4+F21*5+G21*6+H21*7 -> 92
A22: P20 | B22: 1 | C22: 5 | D22: 7 | E22: 10 | I22: =sum(B22:H22) -> 23 | J22: =B22+C22*2+D22*3+E22*4+F22*5+G22*6+H22*7 -> 72
A23: P21 | B23: 5 | C23: 4 | D23: 5 | E23: 3 | F23: 6 | I23: =sum(B23:H23) -> 23 | J23: =B23+C23*2+D23*3+E23*4+F23*5+G23*6+H23*7 -> 70
A24: P22 | B24: 1 | C24: 4 | D24: 4 | E24: 5 | F24: 3 | G24: 6 | I24: =sum(B24:H24) -> 23 | J24: =B24+C24*2+D24*3+E24*4+F24*5+G24*6+H24*7 -> 92
A25: P23 | B25: 1 | C25: 4 | D25: 4 | E25: 5 | F25: 3 | G25: 6 | I25: =sum(B25:H25) -> 23 | J25: =B25+C25*2+D25*3+E25*4+F25*5+G25*6+H25*7 -> 92
A26: P24 | B26: 1 | C26: 4 | D26: 4 | E26: 5 | F26: 3 | G26: 6 | I26: =sum(B26:H26) -> 23 | J26: =B26+C26*2+D26*3+E26*4+F26*5+G26*6+H26*7 -> 92
A29: Alpha 0.4
B30: 1 Edge | C30: 2 Edge | D30: 3 Edge | E30: 4 Edge | F30: 5 Edge | G30: 6 Edge | H30: 7 Edge
A31: P1 | B31: 1 | C31: 6 | D31: 11 | E31: 3 | F31: 2 | I31: =sum(B31:H31) -> 23 | J31: =B31+C31*2+D31*3+E31*4+F31*5+G31*6+H31*7 -> 68 | K31: =sum(J31:J54)/((24*24)-24) -> 2.8876812
A32: P2 | B32: 1 | C32: 6 | D32: 11 | E32: 3 | F32: 2 | I32: =sum(B32:H32) -> 23 | J32: =B32+C32*2+D32*3+E32*4+F32*5+G32*6+H32*7 -> 68
A33: P3 | B33: 1 | C33: 6 | D33: 11 | E33: 3 | F33: 2 | I33: =sum(B33:H33) -> 23 | J33: =B33+C33*2+D33*3+E33*4+F33*5+G33*6+H33*7 -> 68
A34: P4 | B34: 1 | C34: 6 | D34: 11 | E34: 3 | F34: 2 | I34: =sum(B34:H34) -> 23 | J34: =B34+C34*2+D34*3+E34*4+F34*5+G34*6+H34*7 -> 68
A35: P5 | B35: 1 | C35: 6 | D35: 11 | E35: 3 | F35: 2 | I35: =sum(B35:H35) -> 23 | J35: =B35+C35*2+D35*3+E35*4+F35*5+G35*6+H35*7 -> 68
A36: P6 | B36: 7 | C36: 11 | D36: 3 | E36: 2 | I36: =sum(B36:H36) -> 23 | J36: =B36+C36*2+D36*3+E36*4+F36*5+G36*6+H36*7 -> 46
A37: P7 | B37: 1 | C37: 3 | D37: 8 | E37: 3 | F37: 8 | I37: =sum(B37:H37) -> 23 | J37: =B37+C37*2+D37*3+E37*4+F37*5+G37*6+H37*7 -> 83
A38: P8 | B38: 4 | C38: 8 | D38: 3 | E38: 8 | I38: =sum(B38:H38) -> 23 | J38: =B38+C38*2+D38*3+E38*4+F38*5+G38*6+H38*7 -> 61
A39: P9 | B39: 1 | C39: 3 | D39: 8 | E39: 3 | F39: 8 | I39: =sum(B39:H39) -> 23 | J39: =B39+C39*2+D39*3+E39*4+F39*5+G39*6+H39*7 -> 83
A40: P10 | B40: 1 | C40: 3 | D40: 6 | E40: 13 | I40: =sum(B40:H40) -> 23 | J40: =B40+C40*2+D40*3+E40*4+F40*5+G40*6+H40*7 -> 77
A41: P11 | B41: 1 | C41: 3 | D41: 6 | E41: 13 | I41: =sum(B41:H41) -> 23 | J41: =B41+C41*2+D41*3+E41*4+F41*5+G41*6+H41*7 -> 77
A42: P12 | B42: 4 | C42: 6 | D42: 13 | I42: =sum(B42:H42) -> 23 | J42: =B42+C42*2+D42*3+E42*4+F42*5+G42*6+H42*7 -> 55
...

Sheet CHMA
A1: Alpha 0,2
B2: 1 Edge | C2: 2 Edge | D2: 3 Edge | E2: 4 Edge | F2: 5 Edge | G2: 6 Edge | H2: 7 Edge
A3: P1 | B3: 1 | C3: 6 | D3: 4 | E3: 4 | F3: 4 | G3: 4 | I3: =sum(B3:H3) -> 23 | J3: =B3+C3*2+D3*3+E3*4+F3*5+G3*6+H3*7 -> 85 | K3: =sum(J3:J26)/(24*24) -> 3.0625
A4: P2 | B4: 1 | C4: 6 | D4: 4 | E4: 4 | F4: 4 | G4: 4 | I4: =sum(B4:H4) -> 23 | J4: =B4+C4*2+D4*3+E4*4+F4*5+G4*6+H4*7 -> 85
A5: P3 | B5: 1 | C5: 6 | D5: 4 | E5: 4 | F5: 4 | G5: 4 | I5: =sum(B5:H5) -> 23 | J5: =B5+C5*2+D5*3+E5*4+F5*5+G5*6+H5*7 -> 85
A6: P4 | B6: 1 | C6: 6 | D6: 4 | E6: 4 | F6: 4 | G6: 4 | I6: =sum(B6:H6) -> 23 | J6: =B6+C6*2+D6*3+E6*4+F6*5+G6*6+H6*7 -> 85
A7: P5 | B7: 1 | C7: 6 | D7: 4 | E7: 4 | F7: 4 | G7: 4 | I7: =sum(B7:H7) -> 23 | J7: =B7+C7*2+D7*3+E7*4+F7*5+G7*6+H7*7 -> 85
A8: P6 | B8: 7 | C8: 4 | D8: 4 | E8: 4 | F8: 4 | I8: =sum(B8:H8) -> 23 | J8: =B8+C8*2+D8*3+E8*4+F8*5+G8*6+H8*7 -> 63
A9: P7 | B9: 1 | C9: 4 | D9: 10 | E9: 5 | F9: 4 | I9: =sum(B9:H9) -> 24 | J9: =B9+C9*2+D9*3+E9*4+F9*5+G9*6+H9*7 -> 79
A10: P8 | B10: 5 | C10: 10 | D10: 5 | E10: 4 | I10: =sum(B10:H10) -> 24 | J10: =B10+C10*2+D10*3+E10*4+F10*5+G10*6+H10*7 -> 56
A11: P9 | B11: 4 | C11: 10 | D11: 5 | E11: 4 | I11: =sum(B11:H11) -> 23 | J11: =B11+C11*2+D11*3+E11*4+F11*5+G11*6+H11*7 -> 55
A12: P10 | B12: 2 | C12: 7 | D12: 10 | E12: 4 | I12: =sum(B12:H12) -> 23 | J12: =B12+C12*2+D12*3+E12*4+F12*5+G12*6+H12*7 -> 62
A13: P11 | B13: 1 | C13: 6 | D13: 4 | E13: 4 | F13: 4 | G13: 4 | I13: =sum(B13:H13) -> 23 | J13: =B13+C13*2+D13*3+E13*4+F13*5+G13*6+H13*7 -> 85
A14: P12 | B14: 1 | C14: 5 | D14: 7 | E14: 10 | I14: =sum(B14:H14) -> 23 | J14: =B14+C14*2+D14*3+E14*4+F14*5+G14*6+H14*7 -> 72
A15: P13 | B15: 6 | C15: 7 | D15: 10 | I15: =sum(B15:H15) -> 23 | J15: =B15+C15*2+D15*3+E15*4+F15*5+G15*6+H15*7 -> 50
A16: P14 | B16: 1 | C16: 6 | D16: 7 | E16: 3 | F16: 6 | I16: =sum(B16:H16) -> 23 | J16: =B16+C16*2+D16*3+E16*4+F16*5+G16*6+H16*7 -> 76
A17: P15 | B17: 7 | C17: 7 | D17: 3 | E17: 6 | I17: =sum(B17:H17) -> 23 | J17: =B17+C17*2+D17*3+E17*4+F17*5+G17*6+H17*7 -> 54
A18: P16 | B18: 1 | C18: 6 | D18: 7 | E18: 3 | F18: 6 | I18: =sum(B18:H18) -> 23 | J18: =B18+C18*2+D18*3+E18*4+F18*5+G18*6+H18*7 -> 76
A19: P17 | B19: 2 | C19: 8 | D19: 7 | E19: 6 | I19: =sum(B19:H19) -> 23 | J19: =B19+C19*2+D19*3+E19*4+F19*5+G19*6+H19*7 -> 63
A20: P18 | B20: 2 | C20: 8 | D20: 4 | E20: 3 | F20: 6 | I20: =sum(B20:H20) -> 23 | J20: =B20+C20*2+D20*3+E20*4+F20*5+G20*6+H20*7 -> 72
A21: P19 | B21: 1 | C21: 6 | D21: 4 | E21: 3 | F21: 3 | G21: 6 | I21: =sum(B21:H21) -> 23 | J21: =B21+C21*2+D21*3+E21*4+F21*5+G21*6+H21*7 -> 88
A22: P20 | B22: 3 | C22: 11 | D22: 3 | E22: 6 | I22: =sum(B22:H22) -> 23 | J22: =B22+C22*2+D22*3+E22*4+F22*5+G22*6+H22*7 -> 58
A23: P21 | B23: 7 | C23: 4 | D23: 3 | E23: 3 | F23: 6 | I23: =sum(B23:H23) -> 23 | J23: =B23+C23*2+D23*3+E23*4+F23*5+G23*6+H23*7 -> 66
A24: P22 | B24: 1 | C24: 6 | D24: 4 | E24: 3 | F24: 3 | G24: 6 | I24: =sum(B24:H24) -> 23 | J24: =B24+C24*2+D24*3+E24*4+F24*5+G24*6+H24*7 -> 88
A25: P23 | B25: 1 | C25: 6 | D25: 4 | E25: 3 | F25: 3 | G25: 6 | I25: =sum(B25:H25) -> 23 | J25: =B25+C25*2+D25*3+E25*4+F25*5+G25*6+H25*7 -> 88
A26: P24 | B26: 1 | C26: 6 | D26: 4 | E26: 3 | F26: 3 | G26: 6 | I26: =sum(B26:H26) -> 23 | J26: =B26+C26*2+D26*3+E26*4+F26*5+G26*6+H26*7 -> 88
A29: Alpha 0,4
B30: 1 Edge | C30: 2 Edge | D30: 3 Edge | E30: 4 Edge | F30: 5 Edge | G30: 6 Edge | H30: 7 Edge
A31: P1 | B31: 1 | C31: 7 | D31: 3 | E31: 2 | F31: 6 | G31: 4 | I31: =sum(B31:H31) -> 23 | J31: =B31+C31*2+D31*3+E31*4+F31*5+G31*6+H31*7 -> 86 | K31: =sum(J31:J54)/(24*24) -> 2.8958333
A32: P2 | B32: 1 | C32: 7 | D32: 3 | E32: 2 | F32: 6 | G32: 4 | I32: =sum(B32:H32) -> 23 | J32: =B32+C32*2+D32*3+E32*4+F32*5+G32*6+H32*7 -> 86
A33: P3 | B33: 1 | C33: 7 | D33: 3 | E33: 2 | F33: 6 | G33: 4 | I33: =sum(B33:H33) -> 23 | J33: =B33+C33*2+D33*3+E33*4+F33*5+G33*6+H33*7 -> 86
A34: P4 | B34: 1 | C34: 7 | D34: 3 | E34: 2 | F34: 6 | G34: 4 | I34: =sum(B34:H34) -> 23 | J34: =B34+C34*2+D34*3+E34*4+F34*5+G34*6+H34*7 -> 86
A35: P5 | B35: 1 | C35: 7 | D35: 3 | E35: 2 | F35: 6 | G35: 4 | I35: =sum(B35:H35) -> 23 | J35: =B35+C35*2+D35*3+E35*4+F35*5+G35*6+H35*7 -> 86
A36: P6 | B36: 8 | C36: 3 | D36: 2 | E36: 6 | F36: 4 | I36: =sum(B36:H36) -> 23 | J36: =B36+C36*2+D36*3+E36*4+F36*5+G36*6+H36*7 -> 64
A37: P7 | B37: 2 | C37: 9 | D37: 2 | E37: 6 | F37: 4 | I37: =sum(B37:H37) -> 23 | J37: =B37+C37*2+D37*3+E37*4+F37*5+G37*6+H37*7 -> 70
A38: P8 | B38: 5 | C38: 8 | D38: 6 | E38: 4 | I38: =sum(B38:H38) -> 23 | J38: =B38+C38*2+D38*3+E38*4+F38*5+G38*6+H38*7 -> 55
A39: P9 | B39: 2 | C39: 6 | D39: 11 | E39: 4 | I39: =sum(B39:H39) -> 23 | J39: =B39+C39*2+D39*3+E39*4+F39*5+G39*6+H39*7 -> 63
A40: P10 | B40: 3 | C40: 14 | D40: 6 | I40: =sum(B40:H40) -> 23 | J40: =B40+C40*2+D40*3+E40*4+F40*5+G40*6+H40*7 -> 49
A41: P11 | B41: 1 | C41: 6 | D41: 4 | E41: 2 | F41: 6 | G41: 4 | I41: =sum(B41:H41) -> 23 | J41: =B41+C41*2+D41*3+E41*4+F41*5+G41*6+H41*7 -> 87
A42: P12 | B42: 6 | C42: 8 | D42: 9 | I42: =sum(B42:H42) -> 23 | J42: =B42+C42*2+D42*3+E42*4+F42*5+G42*6+H42*7 -> 49
...

Sheet HLSA
A1: Alpha 0.2
B2: 1 Edge | C2: 2 Edge | D2: 3 Edge | E2: 4 Edge | F2: 5 Edge | G2: 6 Edge | H2: 7 Edge
A3: P1 | B3: 1 | C3: 6 | D3: 3 | E3: 5 | F3: 4 | G3: 4 | I3: =sum(B3:H3) -> 23 | J3: =B3+C3*2+D3*3+E3*4+F3*5+G3*6+H3*7 -> 86 | K3: =sum(J3:J26)/((24*24)-24) -> 3.3550725
A4: P2 | B4: 1 | C4: 6 | D4: 3 | E4: 5 | F4: 4 | G4: 4 | I4: =sum(B4:H4) -> 23 | J4: =B4+C4*2+D4*3+E4*4+F4*5+G4*6+H4*7 -> 86
A5: P3 | B5: 1 | C5: 6 | D5: 3 | E5: 5 | F5: 4 | G5: 4 | I5: =sum(B5:H5) -> 23 | J5: =B5+C5*2+D5*3+E5*4+F5*5+G5*6+H5*7 -> 86
A6: P4 | B6: 1 | C6: 6 | D6: 3 | E6: 5 | F6: 4 | G6: 4 | I6: =sum(B6:H6) -> 23 | J6: =B6+C6*2+D6*3+E6*4+F6*5+G6*6+H6*7 -> 86
A7: P5 | B7: 1 | C7: 6 | D7: 3 | E7: 5 | F7: 4 | G7: 4 | I7: =sum(B7:H7) -> 23 | J7: =B7+C7*2+D7*3+E7*4+F7*5+G7*6+H7*7 -> 86
A8: P6 | B8: 7 | C8: 3 | D8: 5 | E8: 4 | F8: 4 | I8: =sum(B8:H8) -> 23 | J8: =B8+C8*2+D8*3+E8*4+F8*5+G8*6+H8*7 -> 64
A9: P7 | B9: 1 | C9: 3 | D9: 11 | E9: 4 | F9: 4 | I9: =sum(B9:H9) -> 23 | J9: =B9+C9*2+D9*3+E9*4+F9*5+G9*6+H9*7 -> 76
A10: P8 | B10: 4 | C10: 11 | D10: 4 | E10: 4 | I10: =sum(B10:H10) -> 23 | J10: =B10+C10*2+D10*3+E10*4+F10*5+G10*6+H10*7 -> 54
A11: P9 | B11: 1 | C11: 3 | D11: 11 | E11: 4 | F11: 4 | I11: =sum(B11:H11) -> 23 | J11: =B11+C11*2+D11*3+E11*4+F11*5+G11*6+H11*7 -> 76
A12: P10 | B12: 1 | C12: 5 | D12: 7 | E12: 10 | I12: =sum(B12:H12) -> 23 | J12: =B12+C12*2+D12*3+E12*4+F12*5+G12*6+H12*7 -> 72
A13: P11 | B13: 1 | C13: 6 | D13: 3 | E13: 5 | F13: 4 | G13: 4 | I13: =sum(B13:H13) -> 23 | J13: =B13+C13*2+D13*3+E13*4+F13*5+G13*6+H13*7 -> 86
A14: P12 | B14: 1 | C14: 5 | D14: 7 | E14: 10 | I14: =sum(B14:H14) -> 23 | J14: =B14+C14*2+D14*3+E14*4+F14*5+G14*6+H14*7 -> 72
A15: P13 | B15: 6 | C15: 7 | D15: 10 | I15: =sum(B15:H15) -> 23 | J15: =B15+C15*2+D15*3+E15*4+F15*5+G15*6+H15*7 -> 50
A16: P14 | B16: 1 | C16: 4 | D16: 9 | E16: 3 | F16: 6 | I16: =sum(B16:H16) -> 23 | J16: =B16+C16*2+D16*3+E16*4+F16*5+G16*6+H16*7 -> 78
A17: P15 | B17: 5 | C17: 9 | D17: 3 | E17: 6 | I17: =sum(B17:H17) -> 23 | J17: =B17+C17*2+D17*3+E17*4+F17*5+G17*6+H17*7 -> 56
A18: P16 | B18: 1 | C18: 4 | D18: 9 | E18: 3 | F18: 6 | I18: =sum(B18:H18) -> 23 | J18: =B18+C18*2+D18*3+E18*4+F18*5+G18*6+H18*7 -> 78
A19: P17 | B19: 1 | C19: 5 | D19: 7 | E19: 10 | I19: =sum(B19:H19) -> 23 | J19: =B19+C19*2+D19*3+E19*4+F19*5+G19*6+H19*7 -> 72
A20: P18 | B20: 1 | C20: 4 | D20: 9 | E20: 3 | F20: 6 | I20: =sum(B20:H20) -> 23 | J20: =B20+C20*2+D20*3+E20*4+F20*5+G20*6+H20*7 -> 78
A21: P19 | B21: 1 | C21: 4 | D21: 4 | E21: 5 | F21: 3 | G21: 6 | I21: =sum(B21:H21) -> 23 | J21: =B21+C21*2+D21*3+E21*4+F21*5+G21*6+H21*7 -> 92
A22: P20 | B22: 1 | C22: 5 | D22: 7 | E22: 10 | I22: =sum(B22:H22) -> 23 | J22: =B22+C22*2+D22*3+E22*4+F22*5+G22*6+H22*7 -> 72
A23: P21 | B23: 5 | C23: 4 | D23: 5 | E23: 3 | F23: 6 | I23: =sum(B23:H23) -> 23 | J23: =B23+C23*2+D23*3+E23*4+F23*5+G23*6+H23*7 -> 70
A24: P22 | B24: 1 | C24: 4 | D24: 4 | E24: 5 | F24: 3 | G24: 6 | I24: =sum(B24:H24) -> 23 | J24: =B24+C24*2+D24*3+E24*4+F24*5+G24*6+H24*7 -> 92
A25: P23 | B25: 1 | C25: 4 | D25: 4 | E25: 5 | F25: 3 | G25: 6 | I25: =sum(B25:H25) -> 23 | J25: =B25+C25*2+D25*3+E25*4+F25*5+G25*6+H25*7 -> 92
A26: P24 | B26: 1 | C26: 4 | D26: 4 | E26: 5 | F26: 3 | G26: 6 | I26: =sum(B26:H26) -> 23 | J26: =B26+C26*2+D26*3+E26*4+F26*5+G26*6+H26*7 -> 92
A29: Alpha 0.4
B30: 1 Edge | C30: 2 Edge | D30: 3 Edge | E30: 4 Edge | F30: 5 Edge | G30: 6 Edge | H30: 7 Edge
A31: P1 | B31: 1 | C31: 5 | D31: 3 | E31: 3 | F31: 3 | G31: 8 | I31: =sum(B31:H31) -> 23 | J31: =B31+C31*2+D31*3+E31*4+F31*5+G31*6+H31*7 -> 95 | K31: =sum(J31:J54)/((24*24)-24) -> 3.4746377
A32: P2 | B32: 1 | C32: 5 | D32: 3 | E32: 3 | F32: 3 | G32: 8 | I32: =sum(B32:H32) -> 23 | J32: =B32+C32*2+D32*3+E32*4+F32*5+G32*6+H32*7 -> 95
A33: P3 | B33: 1 | C33: 5 | D33: 3 | E33: 3 | F33: 3 | G33: 8 | I33: =sum(B33:H33) -> 23 | J33: =B33+C33*2+D33*3+E33*4+F33*5+G33*6+H33*7 -> 95
A34: P4 | B34: 1 | C34: 5 | D34: 3 | E34: 3 | F34: 3 | G34: 8 | I34: =sum(B34:H34) -> 23 | J34: =B34+C34*2+D34*3+E34*4+F34*5+G34*6+H34*7 -> 95
A35: P5 | B35: 1 | C35: 5 | D35: 3 | E35: 3 | F35: 3 | G35: 8 | I35: =sum(B35:H35) -> 23 | J35: =B35+C35*2+D35*3+E35*4+F35*5+G35*6+H35*7 -> 95
A36: P6 | B36: 6 | C36: 3 | D36: 3 | E36: 3 | F36: 8 | I36: =sum(B36:H36) -> 23 | J36: =B36+C36*2+D36*3+E36*4+F36*5+G36*6+H36*7 -> 73
A37: P7 | B37: 1 | C37: 3 | D37: 8 | E37: 3 | F37: 8 | I37: =sum(B37:H37) -> 23 | J37: =B37+C37*2+D37*3+E37*4+F37*5+G37*6+H37*7 -> 83
A38: P8 | B38: 4 | C38: 8 | D38: 3 | E38: 8 | I38: =sum(B38:H38) -> 23 | J38: =B38+C38*2+D38*3+E38*4+F38*5+G38*6+H38*7 -> 61
A39: P9 | B39: 1 | C39: 3 | D39: 8 | E39: 3 | F39: 8 | I39: =sum(B39:H39) -> 23 | J39: =B39+C39*2+D39*3+E39*4+F39*5+G39*6+H39*7 -> 83
A40: P10 | B40: 1 | C40: 3 | D40: 6 | E40: 13 | I40: =sum(B40:H40) -> 23 | J40: =B40+C40*2+D40*3+E40*4+F40*5+G40*6+H40*7 -> 77
A41: P11 | B41: 1 | C41: 3 | D41: 6 | E41: 13 | I41: =sum(B41:H41) -> 23 | J41: =B41+C41*2+D41*3+E41*4+F41*5+G41*6+H41*7 -> 77
A42: P12 | B42: 4 | C42: 6 | D42: 13 | I42: =sum(B42:H42) -> 23 | J42: =B42+C42*2+D42*3+E42*4+F42*5+G42*6+H42*7 -> 55
...

Sheet HLMA
A1: Alpha 0,2
B2: 1 Edge | C2: 2 Edge | D2: 3 Edge | E2: 4 Edge | F2: 5 Edge | G2: 6 Edge | H2: 7 Edge
A3: P1 | B3: 1 | C3: 6 | D3: 4 | E3: 4 | F3: 4 | G3: 4 | I3: =sum(B3:H3) -> 23 | J3: =B3+C3*2+D3*3+E3*4+F3*5+G3*6+H3*7 -> 85 | K3: =sum(J3:J26)/(24*24) -> 3.0625
A4: P2 | B4: 1 | C4: 6 | D4: 4 | E4: 4 | F4: 4 | G4: 4 | I4: =sum(B4:H4) -> 23 | J4: =B4+C4*2+D4*3+E4*4+F4*5+G4*6+H4*7 -> 85
A5: P3 | B5: 1 | C5: 6 | D5: 4 | E5: 4 | F5: 4 | G5: 4 | I5: =sum(B5:H5) -> 23 | J5: =B5+C5*2+D5*3+E5*4+F5*5+G5*6+H5*7 -> 85
A6: P4 | B6: 1 | C6: 6 | D6: 4 | E6: 4 | F6: 4 | G6: 4 | I6: =sum(B6:H6) -> 23 | J6: =B6+C6*2+D6*3+E6*4+F6*5+G6*6+H6*7 -> 85
A7: P5 | B7: 1 | C7: 6 | D7: 4 | E7: 4 | F7: 4 | G7: 4 | I7: =sum(B7:H7) -> 23 | J7: =B7+C7*2+D7*3+E7*4+F7*5+G7*6+H7*7 -> 85
A8: P6 | B8: 7 | C8: 4 | D8: 4 | E8: 4 | F8: 4 | I8: =sum(B8:H8) -> 23 | J8: =B8+C8*2+D8*3+E8*4+F8*5+G8*6+H8*7 -> 63
A9: P7 | B9: 1 | C9: 4 | D9: 10 | E9: 5 | F9: 4 | I9: =sum(B9:H9) -> 24 | J9: =B9+C9*2+D9*3+E9*4+F9*5+G9*6+H9*7 -> 79
A10: P8 | B10: 5 | C10: 10 | D10: 5 | E10: 4 | I10: =sum(B10:H10) -> 24 | J10: =B10+C10*2+D10*3+E10*4+F10*5+G10*6+H10*7 -> 56
A11: P9 | B11: 4 | C11: 10 | D11: 5 | E11: 4 | I11: =sum(B11:H11) -> 23 | J11: =B11+C11*2+D11*3+E11*4+F11*5+G11*6+H11*7 -> 55
A12: P10 | B12: 2 | C12: 7 | D12: 10 | E12: 4 | I12: =sum(B12:H12) -> 23 | J12: =B12+C12*2+D12*3+E12*4+F12*5+G12*6+H12*7 -> 62
A13: P11 | B13: 1 | C13: 6 | D13: 4 | E13: 4 | F13: 4 | G13: 4 | I13: =sum(B13:H13) -> 23 | J13: =B13+C13*2+D13*3+E13*4+F13*5+G13*6+H13*7 -> 85
A14: P12 | B14: 1 | C14: 5 | D14: 7 | E14: 10 | I14: =sum(B14:H14) -> 23 | J14: =B14+C14*2+D14*3+E14*4+F14*5+G14*6+H14*7 -> 72
A15: P13 | B15: 6 | C15: 7 | D15: 10 | I15: =sum(B15:H15) -> 23 | J15: =B15+C15*2+D15*3+E15*4+F15*5+G15*6+H15*7 -> 50
A16: P14 | B16: 1 | C16: 6 | D16: 7 | E16: 3 | F16: 6 | I16: =sum(B16:H16) -> 23 | J16: =B16+C16*2+D16*3+E16*4+F16*5+G16*6+H16*7 -> 76
A17: P15 | B17: 7 | C17: 7 | D17: 3 | E17: 6 | I17: =sum(B17:H17) -> 23 | J17: =B17+C17*2+D17*3+E17*4+F17*5+G17*6+H17*7 -> 54
A18: P16 | B18: 1 | C18: 6 | D18: 7 | E18: 3 | F18: 6 | I18: =sum(B18:H18) -> 23 | J18: =B18+C18*2+D18*3+E18*4+F18*5+G18*6+H18*7 -> 76
A19: P17 | B19: 2 | C19: 8 | D19: 7 | E19: 6 | I19: =sum(B19:H19) -> 23 | J19: =B19+C19*2+D19*3+E19*4+F19*5+G19*6+H19*7 -> 63
A20: P18 | B20: 2 | C20: 8 | D20: 4 | E20: 3 | F20: 6 | I20: =sum(B20:H20) -> 23 | J20: =B20+C20*2+D20*3+E20*4+F20*5+G20*6+H20*7 -> 72
A21: P19 | B21: 1 | C21: 6 | D21: 4 | E21: 3 | F21: 3 | G21: 6 | I21: =sum(B21:H21) -> 23 | J21: =B21+C21*2+D21*3+E21*4+F21*5+G21*6+H21*7 -> 88
A22: P20 | B22: 3 | C22: 11 | D22: 3 | E22: 6 | I22: =sum(B22:H22) -> 23 | J22: =B22+C22*2+D22*3+E22*4+F22*5+G22*6+H22*7 -> 58
A23: P21 | B23: 7 | C23: 4 | D23: 3 | E23: 3 | F23: 6 | I23: =sum(B23:H23) -> 23 | J23: =B23+C23*2+D23*3+E23*4+F23*5+G23*6+H23*7 -> 66
A24: P22 | B24: 1 | C24: 6 | D24: 4 | E24: 3 | F24: 3 | G24: 6 | I24: =sum(B24:H24) -> 23 | J24: =B24+C24*2+D24*3+E24*4+F24*5+G24*6+H24*7 -> 88
A25: P23 | B25: 1 | C25: 6 | D25: 4 | E25: 3 | F25: 3 | G25: 6 | I25: =sum(B25:H25) -> 23 | J25: =B25+C25*2+D25*3+E25*4+F25*5+G25*6+H25*7 -> 88
A26: P24 | B26: 1 | C26: 6 | D26: 4 | E26: 3 | F26: 3 | G26: 6 | I26: =sum(B26:H26) -> 23 | J26: =B26+C26*2+D26*3+E26*4+F26*5+G26*6+H26*7 -> 88
A29: Alpha 0,4
B30: 1 Edge | C30: 2 Edge | D30: 3 Edge | E30: 4 Edge | F30: 5 Edge | G30: 6 Edge | H30: 7 Edge
A31: P1 | B31: 1 | C31: 7 | D31: 3 | E31: 2 | F31: 6 | G31: 4 | I31: =sum(B31:H31) -> 23 | J31: =B31+C31*2+D31*3+E31*4+F31*5+G31*6+H31*7 -> 86 | K31: =sum(J31:J54)/(24*24) -> 2.8958333
A32: P2 | B32: 1 | C32: 7 | D32: 3 | E32: 2 | F32: 6 | G32: 4 | I32: =sum(B32:H32) -> 23 | J32: =B32+C32*2+D32*3+E32*4+F32*5+G32*6+H32*7 -> 86
A33: P3 | B33: 1 | C33: 7 | D33: 3 | E33: 2 | F33: 6 | G33: 4 | I33: =sum(B33:H33) -> 23 | J33: =B33+C33*2+D33*3+E33*4+F33*5+G33*6+H33*7 -> 86
A34: P4 | B34: 1 | C34: 7 | D34: 3 | E34: 2 | F34: 6 | G34: 4 | I34: =sum(B34:H34) -> 23 | J34: =B34+C34*2+D34*3+E34*4+F34*5+G34*6+H34*7 -> 86
A35: P5 | B35: 1 | C35: 7 | D35: 3 | E35: 2 | F35: 6 | G35: 4 | I35: =sum(B35:H35) -> 23 | J35: =B35+C35*2+D35*3+E35*4+F35*5+G35*6+H35*7 -> 86
A36: P6 | B36: 8 | C36: 3 | D36: 2 | E36: 6 | F36: 4 | I36: =sum(B36:H36) -> 23 | J36: =B36+C36*2+D36*3+E36*4+F36*5+G36*6+H36*7 -> 64
A37: P7 | B37: 2 | C37: 9 | D37: 2 | E37: 6 | F37: 4 | I37: =sum(B37:H37) -> 23 | J37: =B37+C37*2+D37*3+E37*4+F37*5+G37*6+H37*7 -> 70
A38: P8 | B38: 5 | C38: 8 | D38: 6 | E38: 4 | I38: =sum(B38:H38) -> 23 | J38: =B38+C38*2+D38*3+E38*4+F38*5+G38*6+H38*7 -> 55
A39: P9 | B39: 2 | C39: 6 | D39: 11 | E39: 4 | I39: =sum(B39:H39) -> 23 | J39: =B39+C39*2+D39*3+E39*4+F39*5+G39*6+H39*7 -> 63
A40: P10 | B40: 3 | C40: 14 | D40: 6 | I40: =sum(B40:H40) -> 23 | J40: =B40+C40*2+D40*3+E40*4+F40*5+G40*6+H40*7 -> 49
A41: P11 | B41: 1 | C41: 6 | D41: 4 | E41: 2 | F41: 6 | G41: 4 | I41: =sum(B41:H41) -> 23 | J41: =B41+C41*2+D41*3+E41*4+F41*5+G41*6+H41*7 -> 87
A42: P12 | B42: 6 | C42: 8 | D42: 9 | I42: =sum(B42:H42) -> 23 | J42: =B42+C42*2+D42*3+E42*4+F42*5+G42*6+H42*7 -> 49
...
