Workbook

Sheet Rekapitulasi
A4: Tipe Model | C4: Fungsi Tujuan | E4: GAP
C5: Cplex | D5: Gsheet
A6: Complete | B6: Single Allocation | C6: 12787558415 | D6: ='Single Allocation'!G2 -> 12787557674 | E6: =(C6-D6)/C6 -> 5.7951364e-08
B7: Multiple Allocation | C7: 12313570417 | D7: ='Multiple Allocation'!G2 -> 12313569957 | E7: =(C7-D7)/C7 -> 3.7369125e-08
A8: Incomplete | B8: Single Allocation | C8: 12787558415 | D8: =Incomplete_SA!J2 -> 12787557674 | E8: =(C8-D8)/C8 -> 5.7951364e-08
B9: Multiple Allocation | C9: 15310629059 | D9: =Incomplete_MA!I2 -> 15310627814 | E9: =(C9-D9)/C9 -> 8.1286391e-08
A10: CycleHub | B10: Single Allocation | C10: 12951617044 | D10: ='Cycle Hub_SA'!E2 -> 12951616463 | E10: =(C10-D10)/C10 -> 4.4896926e-08
B11: Multiple Allocation | C11: 12313570417 | D11: ='Cycle Hub_MA'!G2 -> 12313570446 | E11: =(C11-D11)/C11 -> -2.323179e-09
A12: HubLine | B12: Single Allocation | C12: 13080397914 | D12: =Hubline_SA!H2 -> 13080397928 | E12: =(C12-D12)/C12 -> -1.0325622e-09
B13: Multiple Allocation | C13: 12579311845 | D13: =Hubline_MA!I2 -> 12579311845 | E13: =(C13-D13)/C13 -> 0

Sheet Single Allocation
D1: Objective Function | E1: Cost spoke-hub | F1: cost hub-hub | G1: Total | I1: Cplex
E2: =sum(U8:U17) -> 4530757568 | F2: =sum(M8:M37) -> 8256800106 | G2: =sum(E2:F2) -> 12787557674 | I2: 12787558415 | J2: =G2-I2 -> -741.05646
A3: C | B3: 15
A4: Alpha | B4: 0.75
A6: Hub | D6: Assignemnt | H6: Flow Hub to Hub | O6: Flow Spoke to Hub
A7: Node | B7: is_hub | D7: Origin | E7: Hub | F7: Value | H7: Origin | I7: Hub1 | J7: Hub2 | K7: Flow | L7: Dist | M7: Cost | O7: Origin | P7: Hub | Q7: Value | R7: Origin | S7: Destination | T7: Dist | U7: Cost
A8: P1 | B8: 0 | D8: P1 | E8: P4 | F8: 1 | H8: P1 | I8: P4 | J8: P6 | K8: 12280.84 | L8: {=XLOOKUP(I8, 'Data jarak '!$A$2:$A$11, XLOOKUP(J8, 'Data jarak '!$B$1:$K$1, 'Data jarak '!$B$2:$K$11))} -> 525.4495 | M8: =$B$3*$B$4*K8*L8 -> 72595814 | O8: P1 | P8: P4 | Q8: 1 | R8: =vlookup(O8, Sheet4!$G$1:$I$11,2,0) -> 125092.16 | S8: =vlookup(O8, Sheet4!$G$1:$I$11,3,0) -> 73644.52 | T8: {=XLOOKUP(O8, 'Data jarak '!$A$2:$A$11, XLOOKUP(P8, 'Data jarak '!$B$1:$K$1, 'Data jarak '!$B$2:$K$11))} -> 909.2041 | U8: =$B$3*T8*(R8+S8) -> 2710383064
A9: P2 | B9: 0 | D9: P2 | E9: P4 | F9: 1 | H9: P1 | I9: P4 | J9: P8 | K9: 29375.52 | L9: {=XLOOKUP(I9, 'Data jarak '!$A$2:$A$11, XLOOKUP(J9, 'Data jarak '!$B$1:$K$1, 'Data jarak '!$B$2:$K$11))} -> 918.1315 | M9: =$B$3*$B$4*K9*L9 -> 3.0341914e+08 | O9: P2 | P9: P4 | Q9: 1 | R9: =vlookup(O9, Sheet4!$G$1:$I$11,2,0) -> 30992.74 | S9: =vlookup(O9, Sheet4!$G$1:$I$11,3,0) -> 21308.78 | T9: {=XLOOKUP(O9, 'Data jarak '!$A$2:$A$11, XLOOKUP(P9, 'Data jarak '!$B$1:$K$1, 'Data jarak '!$B$2:$K$11))} -> 563.3406 | U9: =$B$3*T9*(R9+S9) -> 4.4195354e+08
A10: P3 | B10: 0 | D10: P3 | E10: P6 | F10: 1 | H10: P1 | I10: P4 | J10: P10 | K10: 70439.32 | L10: {=XLOOKUP(I10, 'Data jarak '!$A$2:$A$11, XLOOKUP(J10, 'Data jarak '!$B$1:$K$1, 'Data jarak '!$B$2:$K$11))} -> 1535.299 | M10: =$B$3*$B$4*K10*L10 -> 1216635948 | O10: P3 | P10: P6 | Q10: 1 | R10: =vlookup(O10, Sheet4!$G$1:$I$11,2,0) -> 27365.36 | S10: =vlookup(O10, Sheet4!$G$1:$I$11,3,0) -> 48760.24 | T10: {=XLOOKUP(O10, 'Data jarak '!$A$2:$A$11, XLOOKUP(P10, 'Data jarak '!$B$1:$K$1, 'Data jarak '!$B$2:$K$11))} -> 397.4792 | U10: =$B$3*T10*(R10+S10) -> 4.5387514e+08
A11: P4 | B11: 1 | D11: P4 | E11: P4 | F11: 1 | H11: P2 | I11: P4 | J11: P6 | K11: 8739.64 | L11: {=XLOOKUP(I11, 'Data jarak '!$A$2:$A$11, XLOOKUP(J11, 'Data jarak '!$B$1:$K$1, 'Data jarak '!$B$2:$K$11))} -> 525.4495 | M11: =$B$3*$B$4*K11*L11 -> 51662694 | O11: P4 | P11: P4 | Q11: 1 | R11: =vlookup(O11, Sheet4!$G$1:$I$11,2,0) -> 50914.96 | S11: =vlookup(O11, Sheet4!$G$1:$I$11,3,0) -> 147517.64 | T11: {=XLOOKUP(O11, 'Data jarak '!$A$2:$A$11, XLOOKUP(P11, 'Data jarak '!$B$1:$K$1, 'Data jarak '!$B$2:$K$11))} -> 0 | U11: =$B$3*T11*(R11+S11) -> 0
A12: P5 | B12: 0 | D12: P5 | E12: P6 | F12: 1 | H12: P2 | I12: P4 | J12: P8 | K12: 12354.38 | L12: {=XLOOKUP(I12, 'Data jarak '!$A$2:$A$11, XLOOKUP(J12, 'Data jarak '!$B$1:$K$1, 'Data jarak '!$B$2:$K$11))} -> 918.1315 | M12: =$B$3*$B$4*K12*L12 -> 1.2760814e+08 | O12: P5 | P12: P6 | Q12: 1 | R12: =vlookup(O12, Sheet4!$G$1:$I$11,2,0) -> 40906.08 | S12: =vlookup(O12, Sheet4!$G$1:$I$11,3,0) -> 49314.56 | T12: {=XLOOKUP(O12, 'Data jarak '!$A$2:$A$11, XLOOKUP(P12, 'Data jarak '!$B$1:$K$1, 'Data jarak '!$B$2:$K$11))} -> 176.4669 | U12: =$B$3*T12*(R12+S12) -> 2.3881435e+08
A13: P6 | B13: 1 | D13: P6 | E13: P6 | F13: 1 | H13: P2 | I13: P4 | J13: P10 | K13: 4136.76 | L13: {=XLOOKUP(I13, 'Data jarak '!$A$2:$A$11, XLOOKUP(J13, 'Data jarak '!$B$1:$K$1, 'Data jarak '!$B$2:$K$11))} -> 1535.299 | M13: =$B$3*$B$4*K13*L13 -> 71450589 | O13: P6 | P13: P6 | Q13: 1 | R13: =vlookup(O13, Sheet4!$G$1:$I$11,2,0) -> 64470.2 | S13: =vlookup(O13, Sheet4!$G$1:$I$11,3,0) -> 187313.74 | T13: {=XLOOKUP(O13, 'Data jarak '!$A$2:$A$11, XLOOKUP(P13, 'Data jarak '!$B$1:$K$1, 'Data jarak '!$B$2:$K$11))} -> 0 | U13: =$B$3*T13*(R13+S13) -> 0
A14: P7 | B14: 0 | D14: P7 | E14: P8 | F14: 1 | H14: P3 | I14: P6 | J14: P4 | K14: 3746.21 | L14: {=XLOOKUP(I14, 'Data jarak '!$A$2:$A$11, XLOOKUP(J14, 'Data jarak '!$B$1:$K$1, 'Data jarak '!$B$2:$K$11))} -> 525.4495 | M14: =$B$3*$B$4*K14*L14 -> 22144997 | O14: P7 | P14: P8 | Q14: 1 | R14: =vlookup(O14, Sheet4!$G$1:$I$11,2,0) -> 75267.84 | S14: =vlookup(O14, Sheet4!$G$1:$I$11,3,0) -> 44041.76 | T14: {=XLOOKUP(O14, 'Data jarak '!$A$2:$A$11, XLOOKUP(P14, 'Data jarak '!$B$1:$K$1, 'Data jarak '!$B$2:$K$11))} -> 186.18 | U14: =$B$3*T14*(R14+S14) -> 3.3319592e+08
A15: P8 | B15: 1 | D15: P8 | E15: P8 | F15: 1 | H15: P3 | I15: P6 | J15: P8 | K15: 16362.59 | L15: {=XLOOKUP(I15, 'Data jarak '!$A$2:$A$11, XLOOKUP(J15, 'Data jarak '!$B$1:$K$1, 'Data jarak '!$B$2:$K$11))} -> 475.5078 | M15: =$B$3*$B$4*K15*L15 -> 87531066 | O15: P8 | P15: P8 | Q15: 1 | R15: =vlookup(O15, Sheet4!$G$1:$I$11,2,0) -> 420950.02 | S15: =vlookup(O15, Sheet4!$G$1:$I$11,3,0) -> 176319.88 | T15: {=XLOOKUP(O15, 'Data jarak '!$A$2:$A$11, XLOOKUP(P15, 'Data jarak '!$B$1:$K$1, 'Data jarak '!$B$2:$K$11))} -> 0 | U15: =$B$3*T15*(R15+S15) -> 0
A16: P9 | B16: 0 | D16: P9 | E16: P8 | F16: 1 | H16: P3 | I16: P6 | J16: P10 | K16: 2415.04 | L16: {=XLOOKUP(I16, 'Data jarak '!$A$2:$A$11, XLOOKUP(J16, 'Data jarak '!$B$1:$K$1, 'Data jarak '!$B$2:$K$11))} -> 1024.79 | M16: =$B$3*$B$4*K16*L16 -> 27842724 | O16: P9 | P16: P8 | Q16: 1 | R16: =vlookup(O16, Sheet4!$G$1:$I$11,2,0) -> 13888.29 | S16: =vlookup(O16, Sheet4!$G$1:$I$11,3,0) -> 44428.77 | T16: {=XLOOKUP(O16, 'Data jarak '!$A$2:$A$11, XLOOKUP(P16, 'Data jarak '!$B$1:$K$1, 'Data jarak '!$B$2:$K$11))} -> 403.0102 | U16: =$B$3*T16*(R16+S16) -> 3.5253555e+08
A17: P10 | B17: 1 | D17: P10 | E17: P10 | F17: 1 | H17: P4 | I17: P4 | J17: P6 | K17: 11585.16 | L17: {=XLOOKUP(I17, 'Data jarak '!$A$2:$A$11, XLOOKUP(J17, 'Data jarak '!$B$1:$K$1, 'Data jarak '!$B$2:$K$11))} -> 525.4495 | M17: =$B$3*$B$4*K17*L17 -> 68483436 | O17: P10 | P17: P10 | Q17: 1 | R17: =vlookup(O17, Sheet4!$G$1:$I$11,2,0) -> 156335.24 | S17: =vlookup(O17, Sheet4!$G$1:$I$11,3,0) -> 213533 | T17: {=XLOOKUP(O17, 'Data jarak '!$A$2:$A$11, XLOOKUP(P17, 'Data jarak '!$B$1:$K$1, 'Data jarak '!$B$2:$K$11))} -> 0 | U17: =$B$3*T17*(R17+S17) -> 0
H18: P4 | I18: P4 | J18: P8 | K18: 21227.17 | L18: {=XLOOKUP(I18, 'Data jarak '!$A$2:$A$11, XLOOKUP(J18, 'Data jarak '!$B$1:$K$1, 'Data jarak '!$B$2:$K$11))} -> 918.1315 | M18: =$B$3*$B$4*K18*L18 -> 2.19255e+08
H19: P4 | I19: P4 | J19: P10 | K19: 12387.4 | L19: {=XLOOKUP(I19, 'Data jarak '!$A$2:$A$11, XLOOKUP(J19, 'Data jarak '!$B$1:$K$1, 'Data jarak '!$B$2:$K$11))} -> 1535.299 | M19: =$B$3*$B$4*K19*L19 -> 2.1395658e+08
A20: Validasi Routing | H20: P5 | I20: P6 | J20: P4 | K20: 6239.84 | L20: {=XLOOKUP(I20, 'Data jarak '!$A$2:$A$11, XLOOKUP(J20, 'Data jarak '!$B$1:$K$1, 'Data jarak '!$B$2:$K$11))} -> 525.4495 | M20: =$B$3*$B$4*K20*L20 -> 36885609
A21: Pelabuhan Asal | B21: Pelabuhan Tujuan | C21: Hub Awal | D21: Antar Hub | E21: Hub Akhir | F21: Status | H21: P5 | I21: P6 | J21: P8 | K21: 22533.08 | L21: {=XLOOKUP(I21, 'Data jarak '!$A$2:$A$11, XLOOKUP(J21, 'Data jarak '!$B$1:$K$1, 'Data jarak '!$B$2:$K$11))} -> 475.5078 | M21: =$B$3*$B$4*K21*L21 -> 1.2053987e+08
A22: P1 | B22: P10 | C22: P4 | D22: Ada | E22: P10 | F22: Valid | H22: P5 | I22: P6 | J22: P10 | K22: 5911.52 | L22: {=XLOOKUP(I22, 'Data jarak '!$A$2:$A$11, XLOOKUP(J22, 'Data jarak '!$B$1:$K$1, 'Data jarak '!$B$2:$K$11))} -> 1024.79 | M22: =$B$3*$B$4*K22*L22 -> 68153249
A23: P3 | B23: P8 | C23: P6 | D23: Ada | E23: P8 | F23: Valid | H23: P6 | I23: P6 | J23: P4 | K23: 14860.53 | L23: {=XLOOKUP(I23, 'Data jarak '!$A$2:$A$11, XLOOKUP(J23, 'Data jarak '!$B$1:$K$1, 'Data jarak '!$B$2:$K$11))} -> 525.4495 | M23: =$B$3*$B$4*K23*L23 -> 87845153
A24: P5 | B24: P6 | C24: P6 | D24: Ada | E24: P6 | F24: Valid | H24: P6 | I24: P6 | J24: P8 | K24: 38057.03 | L24: {=XLOOKUP(I24, 'Data jarak '!$A$2:$A$11, XLOOKUP(J24, 'Data jarak '!$B$1:$K$1, 'Data jarak '!$B$2:$K$11))} -> 475.5078 | M24: =$B$3*$B$4*K24*L24 -> 2.0358466e+08
A25: P7 | B25: P4 | C25: P8 | D25: Ada | E25: P4 | F25: Valid | H25: P6 | I25: P6 | J25: P10 | K25: 6665.76 | L25: {=XLOOKUP(I25, 'Data jarak '!$A$2:$A$11, XLOOKUP(J25, 'Data jarak '!$B$1:$K$1, 'Data jarak '!$B$2:$K$11))} -> 1024.79 | M25: =$B$3*$B$4*K25*L25 -> 76848797
A26: P9 | B26: P2 | C26: P8 | D26: Ada | E26: P4 | F26: Valid | H26: P7 | I26: P8 | J26: P4 | K26: 12683.13 | L26: {=XLOOKUP(I26, 'Data jarak '!$A$2:$A$11, XLOOKUP(J26, 'Data jarak '!$B$1:$K$1, 'Data jarak '!$B$2:$K$11))} -> 918.1315 | M26: =$B$3*$B$4*K26*L26 -> 1.3100379e+08
H27: P7 | I27: P8 | J27: P6 | K27: 35520.88 | L27: {=XLOOKUP(I27, 'Data jarak '!$A$2:$A$11, XLOOKUP(J27, 'Data jarak '!$B$1:$K$1, 'Data jarak '!$B$2:$K$11))} -> 475.5078 | M27: =$B$3*$B$4*K27*L27 -> 1.9001762e+08
H28: P7 | I28: P8 | J28: P10 | K28: 8546.4 | L28: {=XLOOKUP(I28, 'Data jarak '!$A$2:$A$11, XLOOKUP(J28, 'Data jarak '!$B$1:$K$1, 'Data jarak '!$B$2:$K$11))} -> 658.2451 | M28: =$B$3*$B$4*K28*L28 -> 63288292
H29: P8 | I29: P8 | J29: P4 | K29: 109854.74 | L29: {=XLOOKUP(I29, 'Data jarak '!$A$2:$A$11, XLOOKUP(J29, 'Data jarak '!$B$1:$K$1, 'Data jarak '!$B$2:$K$11))} -> 918.1315 | M29: =$B$3*$B$4*K29*L29 -> 1134687344
H30: P8 | I30: P8 | J30: P6 | K30: 169368.44 | L30: {=XLOOKUP(I30, 'Data jarak '!$A$2:$A$11, XLOOKUP(J30, 'Data jarak '!$B$1:$K$1, 'Data jarak '!$B$2:$K$11))} -> 475.5078 | M30: =$B$3*$B$4*K30*L30 -> 9.0603016e+08
H31: P8 | I31: P8 | J31: P10 | K31: 101245.44 | L31: {=XLOOKUP(I31, 'Data jarak '!$A$2:$A$11, XLOOKUP(J31, 'Data jarak '!$B$1:$K$1, 'Data jarak '!$B$2:$K$11))} -> 658.2451 | M31: =$B$3*$B$4*K31*L31 -> 7.4974854e+08
H32: P9 | I32: P8 | J32: P4 | K32: 3351.92 | L32: {=XLOOKUP(I32, 'Data jarak '!$A$2:$A$11, XLOOKUP(J32, 'Data jarak '!$B$1:$K$1, 'Data jarak '!$B$2:$K$11))} -> 918.1315 | M32: =$B$3*$B$4*K32*L32 -> 34621913
H33: P9 | I33: P8 | J33: P6 | K33: 3799.76 | L33: {=XLOOKUP(I33, 'Data jarak '!$A$2:$A$11, XLOOKUP(J33, 'Data jarak '!$B$1:$K$1, 'Data jarak '!$B$2:$K$11))} -> 475.5078 | M33: =$B$3*$B$4*K33*L33 -> 20326675
H34: P9 | I34: P8 | J34: P10 | K34: 1785.4 | L34: {=XLOOKUP(I34, 'Data jarak '!$A$2:$A$11, XLOOKUP(J34, 'Data jarak '!$B$1:$K$1, 'Data jarak '!$B$2:$K$11))} -> 658.2451 | M34: =$B$3*$B$4*K34*L34 -> 13221347
H35: P10 | I35: P10 | J35: P4 | K35: 67260.9 | L35: {=XLOOKUP(I35, 'Data jarak '!$A$2:$A$11, XLOOKUP(J35, 'Data jarak '!$B$1:$K$1, 'Data jarak '!$B$2:$K$11))} -> 1535.299 | M35: =$B$3*$B$4*K35*L35 -> 1161737916
H36: P10 | I36: P10 | J36: P6 | K36: 28143.8 | L36: {=XLOOKUP(I36, 'Data jarak '!$A$2:$A$11, XLOOKUP(J36, 'Data jarak '!$B$1:$K$1, 'Data jarak '!$B$2:$K$11))} -> 1024.79 | M36: =$B$3*$B$4*K36*L36 -> 324466704
H37: P10 | I37: P10 | J37: P8 | K37: 60930.54 | L37: {=XLOOKUP(I37, 'Data jarak '!$A$2:$A$11, XLOOKUP(J37, 'Data jarak '!$B$1:$K$1, 'Data jarak '!$B$2:$K$11))} -> 658.2451 | M37: =$B$3*$B$4*K37*L37 -> 4.5120633e+08
H42: P1 | I42: 3

Sheet Multiple Allocation
D1: Obj 1 | E1: Obj 2 | F1: Obj 3 | I1: Cplex
C2: Objective Function | D2: =sum(H8:H23) -> 1557482847 | E2: =sum(Q8:Q31) -> 8314943468 | F2: =sum(X8:X97) -> 2441143641 | G2: =sum(D2:F2) -> 12313569957 | I2: 12313570417 | J2: =G2-I2 -> -460.14735
A3: Cs | B3: 15 | G3: valid
A4: Alpha | B4: 0.75
A6: Hub | D6: Assignment | K6: Flow(Yikm) | S6: Flow(Xijm)
A7: Node | B7: is_hub | D7: Origin | E7: Hub | F7: Value | G7: Dist | H7: Cost | K7: Origin | L7: Hub1 | M7: Hub2 | N7: Flow | P7: Dist | Q7: Cost | S7: Origin | T7: destination | U7: Hub | V7: Flow | W7: Dist | X7: Cost | Z7: Validasi Routing
A8: P1 | B8: 1 | D8: P1 | E8: P1 | F8: 125092.16 | G8: {=XLOOKUP(D8, 'Data jarak '!$A$2:$A$11, XLOOKUP(E8, 'Data jarak '!$B$1:$K$1, 'Data jarak '!$B$2:$K$11))} -> 0 | H8: =$B$3*F8*G8 -> 0 | K8: P1 | L8: P1 | M8: P6 | N8: 10334.68 | P8: {=XLOOKUP(L8, 'Data jarak '!$A$2:$A$11, XLOOKUP(M8, 'Data jarak '!$B$1:$K$1, 'Data jarak '!$B$2:$K$11))} -> 1362.65 | Q8: =$B$3*$B$4*N8*P8 -> 1.5842871e+08 | S8: P1 | T8: P2 | U8: P1 | V8: 1460.8 | W8: {=XLOOKUP(T8, 'Data jarak '!$A$2:$A$11, XLOOKUP(U8, 'Data jarak '!$B$1:$K$1, 'Data jarak '!$B$2:$K$11))} -> 404.8972 | X8: =$B$3*V8*W8 -> 8872107.4 | Z8: Pelabuhan Asal | AA8: Pelabuhan Tujuan | AB8: Hub Awal | AC8: Antar Hub | AD8: Hub Akhir | AE8: Status
A9: P2 | B9: 0 | D9: P2 | E9: P1 | F9: 5761.96 | G9: {=XLOOKUP(D9, 'Data jarak '!$A$2:$A$11, XLOOKUP(E9, 'Data jarak '!$B$1:$K$1, 'Data jarak '!$B$2:$K$11))} -> 404.8972 | H9: =$B$3*F9*G9 -> 34995022 | K9: P1 | L9: P1 | M9: P8 | N9: 26992.84 | P9: {=XLOOKUP(L9, 'Data jarak '!$A$2:$A$11, XLOOKUP(M9, 'Data jarak '!$B$1:$K$1, 'Data jarak '!$B$2:$K$11))} -> 1810.495 | Q9: =$B$3*$B$4*N9*P9 -> 5.4979202e+08 | S9: P1 | T9: P3 | U9: P1 | V9: 1864.4 | W9: {=XLOOKUP(T9, 'Data jarak '!$A$2:$A$11, XLOOKUP(U9, 'Data jarak '!$B$1:$K$1, 'Data jarak '!$B$2:$K$11))} -> 1061.869 | X9: =$B$3*V9*W9 -> 29696228 | Z9: P1 | AA9: P10 | AB9: P4 | AC9: Ada | AD9: P10 | AE9: Valid
A10: P3 | B10: 0 | D10: P2 | E10: P6 | F10: 25230.78 | G10: {=XLOOKUP(D10, 'Data jarak '!$A$2:$A$11, XLOOKUP(E10, 'Data jarak '!$B$1:$K$1, 'Data jarak '!$B$2:$K$11))} -> 966.6815 | H10: =$B$3*F10*G10 -> 3.6585192e+08 | K10: P1 | L10: P1 | M10: P10 | N10: 70439.32 | P10: {=XLOOKUP(L10, 'Data jarak '!$A$2:$A$11, XLOOKUP(M10, 'Data jarak '!$B$1:$K$1, 'Data jarak '!$B$2:$K$11))} -> 2382.411 | Q10: =$B$3*$B$4*N10*P10 -> 1887923372 | S10: P1 | T10: P4 | U10: P1 | V10: 11535.68 | W10: {=XLOOKUP(T10, 'Data jarak '!$A$2:$A$11, XLOOKUP(U10, 'Data jarak '!$B$1:$K$1, 'Data jarak '!$B$2:$K$11))} -> 909.2041 | X10: =$B$3*V10*W10 -> 1.5732431e+08 | Z10: P3 | AA10: P8 | AB10: P8 | AC10: Tidak | AD10: P8 | AE10: Valid
A11: P4 | B11: 0 | D11: P3 | E11: P1 | F11: 881.92 | G11: {=XLOOKUP(D11, 'Data jarak '!$A$2:$A$11, XLOOKUP(E11, 'Data jarak '!$B$1:$K$1, 'Data jarak '!$B$2:$K$11))} -> 1061.869 | H11: =$B$3*F11*G11 -> 14047253 | K11: P2 | L11: P6 | M11: P8 | N11: 9718.65 | P11: {=XLOOKUP(L11, 'Data jarak '!$A$2:$A$11, XLOOKUP(M11, 'Data jarak '!$B$1:$K$1, 'Data jarak '!$B$2:$K$11))} -> 475.5078 | Q11: =$B$3*$B$4*N11*P11 -> 51989556 | S11: P1 | T11: P5 | U11: P1 | V11: 2464.44 | W11: {=XLOOKUP(T11, 'Data jarak '!$A$2:$A$11, XLOOKUP(U11, 'Data jarak '!$B$1:$K$1, 'Data jarak '!$B$2:$K$11))} -> 1187.826 | X11: =$B$3*V11*W11 -> 43909889 | Z11: P5 | AA11: P6 | AB11: P6 | AC11: Tidak | AD11: P6 | AE11: Valid
A12: P5 | B12: 0 | D12: P3 | E12: P6 | F12: 26483.44 | G12: {=XLOOKUP(D12, 'Data jarak '!$A$2:$A$11, XLOOKUP(E12, 'Data jarak '!$B$1:$K$1, 'Data jarak '!$B$2:$K$11))} -> 397.4792 | H12: =$B$3*F12*G12 -> 1.5789925e+08 | K12: P2 | L12: P6 | M12: P10 | N12: 4136.76 | P12: {=XLOOKUP(L12, 'Data jarak '!$A$2:$A$11, XLOOKUP(M12, 'Data jarak '!$B$1:$K$1, 'Data jarak '!$B$2:$K$11))} -> 1024.79 | Q12: =$B$3*$B$4*N12*P12 -> 47692241 | S12: P1 | T12: P6 | U12: P6 | V12: 7952 | W12: {=XLOOKUP(T12, 'Data jarak '!$A$2:$A$11, XLOOKUP(U12, 'Data jarak '!$B$1:$K$1, 'Data jarak '!$B$2:$K$11))} -> 0 | X12: =$B$3*V12*W12 -> 0 | Z12: P7 | AA12: P4 | AB12: P4 | AC12: Tidak | AD12: P4 | AE12: Valid
A13: P6 | B13: 1 | D13: P4 | E13: P1 | F13: 5715.23 | G13: {=XLOOKUP(D13, 'Data jarak '!$A$2:$A$11, XLOOKUP(E13, 'Data jarak '!$B$1:$K$1, 'Data jarak '!$B$2:$K$11))} -> 909.2041 | H13: =$B$3*F13*G13 -> 77944658 | K13: P3 | L13: P6 | M13: P8 | N13: 5883.31 | P13: {=XLOOKUP(L13, 'Data jarak '!$A$2:$A$11, XLOOKUP(M13, 'Data jarak '!$B$1:$K$1, 'Data jarak '!$B$2:$K$11))} -> 475.5078 | Q13: =$B$3*$B$4*N13*P13 -> 31472548 | S13: P1 | T13: P7 | U13: P6 | V13: 2382.68 | W13: {=XLOOKUP(T13, 'Data jarak '!$A$2:$A$11, XLOOKUP(U13, 'Data jarak '!$B$1:$K$1, 'Data jarak '!$B$2:$K$11))} -> 356.1662 | X13: =$B$3*V13*W13 -> 12729451 | Z13: P9 | AA13: P2 | AB13: P8 | AC13: Ada | AD13: P4 | AE13: Valid
A14: P7 | B14: 0 | D14: P4 | E14: P6 | F14: 45199.73 | G14: {=XLOOKUP(D14, 'Data jarak '!$A$2:$A$11, XLOOKUP(E14, 'Data jarak '!$B$1:$K$1, 'Data jarak '!$B$2:$K$11))} -> 525.4495 | H14: =$B$3*F14*G14 -> 3.5625263e+08 | K14: P3 | L14: P6 | M14: P10 | N14: 2415.04 | P14: {=XLOOKUP(L14, 'Data jarak '!$A$2:$A$11, XLOOKUP(M14, 'Data jarak '!$B$1:$K$1, 'Data jarak '!$B$2:$K$11))} -> 1024.79 | Q14: =$B$3*$B$4*N14*P14 -> 27842724 | S14: P1 | T14: P8 | U14: P8 | V14: 24726.24 | W14: {=XLOOKUP(T14, 'Data jarak '!$A$2:$A$11, XLOOKUP(U14, 'Data jarak '!$B$1:$K$1, 'Data jarak '!$B$2:$K$11))} -> 0 | X14: =$B$3*V14*W14 -> 0
A15: P8 | B15: 1 | D15: P5 | E15: P1 | F15: 1916.56 | G15: {=XLOOKUP(D15, 'Data jarak '!$A$2:$A$11, XLOOKUP(E15, 'Data jarak '!$B$1:$K$1, 'Data jarak '!$B$2:$K$11))} -> 1187.826 | H15: =$B$3*F15*G15 -> 34148097 | K15: P4 | L15: P6 | M15: P8 | N15: 18203.37 | P15: {=XLOOKUP(L15, 'Data jarak '!$A$2:$A$11, XLOOKUP(M15, 'Data jarak '!$B$1:$K$1, 'Data jarak '!$B$2:$K$11))} -> 475.5078 | Q15: =$B$3*$B$4*N15*P15 -> 97378250 | S15: P1 | T15: P9 | U15: P8 | V15: 2266.6 | W15: {=XLOOKUP(T15, 'Data jarak '!$A$2:$A$11, XLOOKUP(U15, 'Data jarak '!$B$1:$K$1, 'Data jarak '!$B$2:$K$11))} -> 403.0102 | X15: =$B$3*V15*W15 -> 13701944
A16: P9 | B16: 0 | D16: P5 | E16: P6 | F16: 38989.52 | G16: {=XLOOKUP(D16, 'Data jarak '!$A$2:$A$11, XLOOKUP(E16, 'Data jarak '!$B$1:$K$1, 'Data jarak '!$B$2:$K$11))} -> 176.4669 | H16: =$B$3*F16*G16 -> 1.032054e+08 | K16: P4 | L16: P6 | M16: P10 | N16: 12387.4 | P16: {=XLOOKUP(L16, 'Data jarak '!$A$2:$A$11, XLOOKUP(M16, 'Data jarak '!$B$1:$K$1, 'Data jarak '!$B$2:$K$11))} -> 1024.79 | Q16: =$B$3*$B$4*N16*P16 -> 142812941 | S16: P1 | T16: P10 | U16: P10 | V16: 70439.32 | W16: {=XLOOKUP(T16, 'Data jarak '!$A$2:$A$11, XLOOKUP(U16, 'Data jarak '!$B$1:$K$1, 'Data jarak '!$B$2:$K$11))} -> 0 | X16: =$B$3*V16*W16 -> 0
A17: P10 | B17: 1 | D17: P6 | E17: P6 | F17: 64470.2 | G17: {=XLOOKUP(D17, 'Data jarak '!$A$2:$A$11, XLOOKUP(E17, 'Data jarak '!$B$1:$K$1, 'Data jarak '!$B$2:$K$11))} -> 0 | H17: =$B$3*F17*G17 -> 0 | K17: P5 | L17: P6 | M17: P8 | N17: 21555.56 | P17: {=XLOOKUP(L17, 'Data jarak '!$A$2:$A$11, XLOOKUP(M17, 'Data jarak '!$B$1:$K$1, 'Data jarak '!$B$2:$K$11))} -> 475.5078 | Q17: =$B$3*$B$4*N17*P17 -> 1.1531067e+08 | S17: P2 | T17: P1 | U17: P1 | V17: 1517.87 | W17: {=XLOOKUP(T17, 'Data jarak '!$A$2:$A$11, XLOOKUP(U17, 'Data jarak '!$B$1:$K$1, 'Data jarak '!$B$2:$K$11))} -> 0 | X17: =$B$3*V17*W17 -> 0
D18: P7 | E18: P6 | F18: 48204.01 | G18: {=XLOOKUP(D18, 'Data jarak '!$A$2:$A$11, XLOOKUP(E18, 'Data jarak '!$B$1:$K$1, 'Data jarak '!$B$2:$K$11))} -> 356.1662 | H18: =$B$3*F18*G18 -> 257529586 | K18: P5 | L18: P6 | M18: P10 | N18: 5911.52 | P18: {=XLOOKUP(L18, 'Data jarak '!$A$2:$A$11, XLOOKUP(M18, 'Data jarak '!$B$1:$K$1, 'Data jarak '!$B$2:$K$11))} -> 1024.79 | Q18: =$B$3*$B$4*N18*P18 -> 68153249 | S18: P2 | T18: P3 | U18: P6 | V18: 1940.46 | W18: {=XLOOKUP(T18, 'Data jarak '!$A$2:$A$11, XLOOKUP(U18, 'Data jarak '!$B$1:$K$1, 'Data jarak '!$B$2:$K$11))} -> 397.4792 | X18: =$B$3*V18*W18 -> 11569387
D19: P7 | E19: P8 | F19: 27063.83 | G19: {=XLOOKUP(D19, 'Data jarak '!$A$2:$A$11, XLOOKUP(E19, 'Data jarak '!$B$1:$K$1, 'Data jarak '!$B$2:$K$11))} -> 186.18 | H19: =$B$3*F19*G19 -> 75581158 | K19: P6 | L19: P6 | M19: P1 | N19: 2334.6 | P19: {=XLOOKUP(L19, 'Data jarak '!$A$2:$A$11, XLOOKUP(M19, 'Data jarak '!$B$1:$K$1, 'Data jarak '!$B$2:$K$11))} -> 1362.65 | Q19: =$B$3*$B$4*N19*P19 -> 35788980 | S19: P2 | T19: P4 | U19: P1 | V19: 4244.09 | W19: {=XLOOKUP(T19, 'Data jarak '!$A$2:$A$11, XLOOKUP(U19, 'Data jarak '!$B$1:$K$1, 'Data jarak '!$B$2:$K$11))} -> 909.2041 | X19: =$B$3*V19*W19 -> 57881160
D20: P8 | E20: P8 | F20: 420950.08 | G20: {=XLOOKUP(D20, 'Data jarak '!$A$2:$A$11, XLOOKUP(E20, 'Data jarak '!$B$1:$K$1, 'Data jarak '!$B$2:$K$11))} -> 0 | H20: =$B$3*F20*G20 -> 0 | K20: P6 | L20: P6 | M20: P8 | N20: 35521.71 | P20: {=XLOOKUP(L20, 'Data jarak '!$A$2:$A$11, XLOOKUP(M20, 'Data jarak '!$B$1:$K$1, 'Data jarak '!$B$2:$K$11))} -> 475.5078 | Q20: =$B$3*$B$4*N20*P20 -> 1.9002206e+08 | S20: P2 | T20: P5 | U20: P6 | V20: 547.44 | W20: {=XLOOKUP(T20, 'Data jarak '!$A$2:$A$11, XLOOKUP(U20, 'Data jarak '!$B$1:$K$1, 'Data jarak '!$B$2:$K$11))} -> 176.4669 | X20: =$B$3*V20*W20 -> 1449075.6
D21: P9 | E21: P8 | F21: 12102.89 | G21: {=XLOOKUP(D21, 'Data jarak '!$A$2:$A$11, XLOOKUP(E21, 'Data jarak '!$B$1:$K$1, 'Data jarak '!$B$2:$K$11))} -> 403.0102 | H21: =$B$3*F21*G21 -> 73163822 | K21: P6 | L21: P6 | M21: P10 | N21: 6665.76 | P21: {=XLOOKUP(L21, 'Data jarak '!$A$2:$A$11, XLOOKUP(M21, 'Data jarak '!$B$1:$K$1, 'Data jarak '!$B$2:$K$11))} -> 1024.79 | Q21: =$B$3*$B$4*N21*P21 -> 76848797 | S21: P2 | T21: P6 | U21: P6 | V21: 6251.74 | W21: {=XLOOKUP(T21, 'Data jarak '!$A$2:$A$11, XLOOKUP(U21, 'Data jarak '!$B$1:$K$1, 'Data jarak '!$B$2:$K$11))} -> 0 | X21: =$B$3*V21*W21 -> 0
D22: P9 | E22: P10 | F22: 1785.4 | G22: {=XLOOKUP(D22, 'Data jarak '!$A$2:$A$11, XLOOKUP(E22, 'Data jarak '!$B$1:$K$1, 'Data jarak '!$B$2:$K$11))} -> 256.303 | H22: =$B$3*F22*G22 -> 6864050.6 | K22: P7 | L22: P6 | M22: P1 | N22: 2873.96 | P22: {=XLOOKUP(L22, 'Data jarak '!$A$2:$A$11, XLOOKUP(M22, 'Data jarak '!$B$1:$K$1, 'Data jarak '!$B$2:$K$11))} -> 1362.65 | Q22: =$B$3*$B$4*N22*P22 -> 44057268 | S22: P2 | T22: P7 | U22: P6 | V22: 2635.73 | W22: {=XLOOKUP(T22, 'Data jarak '!$A$2:$A$11, XLOOKUP(U22, 'Data jarak '!$B$1:$K$1, 'Data jarak '!$B$2:$K$11))} -> 356.1662 | X22: =$B$3*V22*W22 -> 14081369
D23: P10 | E23: P10 | F23: 156335.24 | G23: {=XLOOKUP(D23, 'Data jarak '!$A$2:$A$11, XLOOKUP(E23, 'Data jarak '!$B$1:$K$1, 'Data jarak '!$B$2:$K$11))} -> 0 | H23: =$B$3*F23*G23 -> 0 | K23: P7 | L23: P8 | M23: P10 | N23: 8546.4 | P23: {=XLOOKUP(L23, 'Data jarak '!$A$2:$A$11, XLOOKUP(M23, 'Data jarak '!$B$1:$K$1, 'Data jarak '!$B$2:$K$11))} -> 658.2451 | Q23: =$B$3*$B$4*N23*P23 -> 63288292 | S23: P2 | T23: P8 | U23: P8 | V23: 6039.82 | W23: {=XLOOKUP(T23, 'Data jarak '!$A$2:$A$11, XLOOKUP(U23, 'Data jarak '!$B$1:$K$1, 'Data jarak '!$B$2:$K$11))} -> 0 | X23: =$B$3*V23*W23 -> 0
K24: P8 | L24: P8 | M24: P1 | N24: 30724.48 | P24: {=XLOOKUP(L24, 'Data jarak '!$A$2:$A$11, XLOOKUP(M24, 'Data jarak '!$B$1:$K$1, 'Data jarak '!$B$2:$K$11))} -> 1810.495 | Q24: =$B$3*$B$4*N24*P24 -> 6.2579832e+08 | S24: P2 | T24: P9 | U24: P8 | V24: 3678.83 | W24: {=XLOOKUP(T24, 'Data jarak '!$A$2:$A$11, XLOOKUP(U24, 'Data jarak '!$B$1:$K$1, 'Data jarak '!$B$2:$K$11))} -> 403.0102 | X24: =$B$3*V24*W24 -> 22239090
K25: P8 | L25: P8 | M25: P6 | N25: 248498.7 | P25: {=XLOOKUP(L25, 'Data jarak '!$A$2:$A$11, XLOOKUP(M25, 'Data jarak '!$B$1:$K$1, 'Data jarak '!$B$2:$K$11))} -> 475.5078 | Q25: =$B$3*$B$4*N25*P25 -> 1329334539 | S25: P2 | T25: P10 | U25: P10 | V25: 4136.76 | W25: {=XLOOKUP(T25, 'Data jarak '!$A$2:$A$11, XLOOKUP(U25, 'Data jarak '!$B$1:$K$1, 'Data jarak '!$B$2:$K$11))} -> 0 | X25: =$B$3*V25*W25 -> 0
K26: P8 | L26: P8 | M26: P10 | N26: 101245.44 | P26: {=XLOOKUP(L26, 'Data jarak '!$A$2:$A$11, XLOOKUP(M26, 'Data jarak '!$B$1:$K$1, 'Data jarak '!$B$2:$K$11))} -> 658.2451 | Q26: =$B$3*$B$4*N26*P26 -> 7.4974854e+08 | S26: P3 | T26: P1 | U26: P1 | V26: 881.92 | W26: {=XLOOKUP(T26, 'Data jarak '!$A$2:$A$11, XLOOKUP(U26, 'Data jarak '!$B$1:$K$1, 'Data jarak '!$B$2:$K$11))} -> 0 | X26: =$B$3*V26*W26 -> 0
K27: P9 | L27: P8 | M27: P1 | N27: 535.69 | P27: {=XLOOKUP(L27, 'Data jarak '!$A$2:$A$11, XLOOKUP(M27, 'Data jarak '!$B$1:$K$1, 'Data jarak '!$B$2:$K$11))} -> 1810.495 | Q27: =$B$3*$B$4*N27*P27 -> 10910971 | S27: P3 | T27: P2 | U27: P6 | V27: 768.89 | W27: {=XLOOKUP(T27, 'Data jarak '!$A$2:$A$11, XLOOKUP(U27, 'Data jarak '!$B$1:$K$1, 'Data jarak '!$B$2:$K$11))} -> 966.6815 | X27: =$B$3*V27*W27 -> 11149076
K28: P9 | L28: P8 | M28: P6 | N28: 6615.99 | P28: {=XLOOKUP(L28, 'Data jarak '!$A$2:$A$11, XLOOKUP(M28, 'Data jarak '!$B$1:$K$1, 'Data jarak '!$B$2:$K$11))} -> 475.5078 | Q28: =$B$3*$B$4*N28*P28 -> 35391992 | S28: P3 | T28: P4 | U28: P6 | V28: 2095.4 | W28: {=XLOOKUP(T28, 'Data jarak '!$A$2:$A$11, XLOOKUP(U28, 'Data jarak '!$B$1:$K$1, 'Data jarak '!$B$2:$K$11))} -> 525.4495 | X28: =$B$3*V28*W28 -> 16515403
K29: P10 | L29: P10 | M29: P1 | N29: 29981.56 | P29: {=XLOOKUP(L29, 'Data jarak '!$A$2:$A$11, XLOOKUP(M29, 'Data jarak '!$B$1:$K$1, 'Data jarak '!$B$2:$K$11))} -> 2382.411 | Q29: =$B$3*$B$4*N29*P29 -> 8.0356948e+08 | S29: P3 | T29: P5 | U29: P6 | V29: 575.8 | W29: {=XLOOKUP(T29, 'Data jarak '!$A$2:$A$11, XLOOKUP(U29, 'Data jarak '!$B$1:$K$1, 'Data jarak '!$B$2:$K$11))} -> 176.4669 | X29: =$B$3*V29*W29 -> 1524144.6
K30: P10 | L30: P10 | M30: P6 | N30: 65423.14 | P30: {=XLOOKUP(L30, 'Data jarak '!$A$2:$A$11, XLOOKUP(M30, 'Data jarak '!$B$1:$K$1, 'Data jarak '!$B$2:$K$11))} -> 1024.79 | Q30: =$B$3*$B$4*N30*P30 -> 754256021 | S30: P3 | T30: P6 | U30: P6 | V30: 4265.72 | W30: {=XLOOKUP(T30, 'Data jarak '!$A$2:$A$11, XLOOKUP(U30, 'Data jarak '!$B$1:$K$1, 'Data jarak '!$B$2:$K$11))} -> 0 | X30: =$B$3*V30*W30 -> 0
K31: P10 | L31: P10 | M31: P8 | N31: 56329.16 | P31: {=XLOOKUP(L31, 'Data jarak '!$A$2:$A$11, XLOOKUP(M31, 'Data jarak '!$B$1:$K$1, 'Data jarak '!$B$2:$K$11))} -> 658.2451 | Q31: =$B$3*$B$4*N31*P31 -> 4.1713193e+08 | S31: P3 | T31: P7 | U31: P6 | V31: 10479.28 | W31: {=XLOOKUP(T31, 'Data jarak '!$A$2:$A$11, XLOOKUP(U31, 'Data jarak '!$B$1:$K$1, 'Data jarak '!$B$2:$K$11))} -> 356.1662 | X31: =$B$3*V31*W31 -> 55985480
S32: P3 | T32: P8 | U32: P8 | V32: 5041.36 | W32: {=XLOOKUP(T32, 'Data jarak '!$A$2:$A$11, XLOOKUP(U32, 'Data jarak '!$B$1:$K$1, 'Data jarak '!$B$2:$K$11))} -> 0 | X32: =$B$3*V32*W32 -> 0
S33: P3 | T33: P9 | U33: P8 | V33: 841.95 | W33: {=XLOOKUP(T33, 'Data jarak '!$A$2:$A$11, XLOOKUP(U33, 'Data jarak '!$B$1:$K$1, 'Data jarak '!$B$2:$K$11))} -> 403.0102 | X33: =$B$3*V33*W33 -> 5089716.6
S34: P3 | T34: P10 | U34: P10 | V34: 2415.04 | W34: {=XLOOKUP(T34, 'Data jarak '!$A$2:$A$11, XLOOKUP(U34, 'Data jarak '!$B$1:$K$1, 'Data jarak '!$B$2:$K$11))} -> 0 | X34: =$B$3*V34*W34 -> 0
S35: P4 | T35: P1 | U35: P1 | V35: 2877.88 | W35: {=XLOOKUP(T35, 'Data jarak '!$A$2:$A$11, XLOOKUP(U35, 'Data jarak '!$B$1:$K$1, 'Data jarak '!$B$2:$K$11))} -> 0 | X35: =$B$3*V35*W35 -> 0
S36: P4 | T36: P2 | U36: P1 | V36: 2837.35 | W36: {=XLOOKUP(T36, 'Data jarak '!$A$2:$A$11, XLOOKUP(U36, 'Data jarak '!$B$1:$K$1, 'Data jarak '!$B$2:$K$11))} -> 404.8972 | X36: =$B$3*V36*W36 -> 17232526
S37: P4 | T37: P3 | U37: P6 | V37: 2340.64 | W37: {=XLOOKUP(T37, 'Data jarak '!$A$2:$A$11, XLOOKUP(U37, 'Data jarak '!$B$1:$K$1, 'Data jarak '!$B$2:$K$11))} -> 397.4792 | X37: =$B$3*V37*W37 -> 13955336
K38: average 3 | S38: P4 | T38: P5 | U38: P6 | V38: 1346.84 | W38: {=XLOOKUP(T38, 'Data jarak '!$A$2:$A$11, XLOOKUP(U38, 'Data jarak '!$B$1:$K$1, 'Data jarak '!$B$2:$K$11))} -> 176.4669 | X38: =$B$3*V38*W38 -> 3565090.2
S39: P4 | T39: P6 | U39: P6 | V39: 7897.68 | W39: {=XLOOKUP(T39, 'Data jarak '!$A$2:$A$11, XLOOKUP(U39, 'Data jarak '!$B$1:$K$1, 'Data jarak '!$B$2:$K$11))} -> 0 | X39: =$B$3*V39*W39 -> 0
S40: P4 | T40: P7 | U40: P6 | V40: 3023.8 | W40: {=XLOOKUP(T40, 'Data jarak '!$A$2:$A$11, XLOOKUP(U40, 'Data jarak '!$B$1:$K$1, 'Data jarak '!$B$2:$K$11))} -> 356.1662 | X40: =$B$3*V40*W40 -> 16154630
S41: P4 | T41: P8 | U41: P8 | V41: 15699.2 | W41: {=XLOOKUP(T41, 'Data jarak '!$A$2:$A$11, XLOOKUP(U41, 'Data jarak '!$B$1:$K$1, 'Data jarak '!$B$2:$K$11))} -> 0 | X41: =$B$3*V41*W41 -> 0
...

Sheet Copy of Multiple Allocation
D1: Obj 1 | E1: Obj 2 | F1: Obj 3 | I1: Cplex
C2: Objective Function | D2: =sum(H8:H23) -> #N/A | E2: =sum(Q8:Q31) -> 8314943468 | F2: =sum(X8:X97) -> 2441143641 | G2: =sum(D2:F2) -> #N/A | I2: 12313570417 | J2: =G2-I2 -> #N/A
A3: Cs | B3: 15 | G3: valid
A4: Alpha | B4: 0.75
A6: Hub | D6: Assignment | K6: Flow(Yikm) | S6: Flow(Xijm)
A7: Node | B7: is_hub | D7: Origin | E7: Hub | F7: Value | G7: Dist | H7: Cost | K7: Origin | L7: Hub1 | M7: Hub2 | N7: Flow | P7: Dist | Q7: Cost | S7: Origin | T7: destination | U7: Hub | V7: Flow | W7: Dist | X7: Cost | Z7: Validasi Routing
A8: P1 | B8: 0 | D8: P1 | E8: P6 | F8: 219823.16 | G8: {=XLOOKUP(D8, 'Data jarak '!$A$2:$A$11, XLOOKUP(E8, 'Data jarak '!$B$1:$K$1, 'Data jarak '!$B$2:$K$11))} -> 1362.65 | H8: =$B$3*F8*G8 -> 4493130435 | K8: P1 | L8: P1 | M8: P6 | N8: 10334.68 | P8: {=XLOOKUP(L8, 'Data jarak '!$A$2:$A$11, XLOOKUP(M8, 'Data jarak '!$B$1:$K$1, 'Data jarak '!$B$2:$K$11))} -> 1362.65 | Q8: =$B$3*$B$4*N8*P8 -> 1.5842871e+08 | S8: P1 | T8: P2 | U8: P1 | V8: 1460.8 | W8: {=XLOOKUP(T8, 'Data jarak '!$A$2:$A$11, XLOOKUP(U8, 'Data jarak '!$B$1:$K$1, 'Data jarak '!$B$2:$K$11))} -> 404.8972 | X8: =$B$3*V8*W8 -> 8872107.4 | Z8: Pelabuhan Asal | AA8: Pelabuhan Tujuan | AB8: Hub Awal | AC8: Antar Hub | AD8: Hub Akhir | AE8: Status
A9: P2 | B9: 0 | D9: P2 | E9: P6 | F9: 113722.62 | G9: {=XLOOKUP(D9, 'Data jarak '!$A$2:$A$11, XLOOKUP(E9, 'Data jarak '!$B$1:$K$1, 'Data jarak '!$B$2:$K$11))} -> 966.6815 | H9: =$B$3*F9*G9 -> 1649003293 | K9: P1 | L9: P1 | M9: P8 | N9: 26992.84 | P9: {=XLOOKUP(L9, 'Data jarak '!$A$2:$A$11, XLOOKUP(M9, 'Data jarak '!$B$1:$K$1, 'Data jarak '!$B$2:$K$11))} -> 1810.495 | Q9: =$B$3*$B$4*N9*P9 -> 5.4979202e+08 | S9: P1 | T9: P3 | U9: P1 | V9: 1864.4 | W9: {=XLOOKUP(T9, 'Data jarak '!$A$2:$A$11, XLOOKUP(U9, 'Data jarak '!$B$1:$K$1, 'Data jarak '!$B$2:$K$11))} -> 1061.869 | X9: =$B$3*V9*W9 -> 29696228 | Z9: P1 | AA9: P10 | AB9: P4 | AC9: Ada | AD9: P10 | AE9: Valid
A10: P3 | B10: 0 | D10: P3 | E10: P6 | F10: 127542.2 | G10: {=XLOOKUP(D10, 'Data jarak '!$A$2:$A$11, XLOOKUP(E10, 'Data jarak '!$B$1:$K$1, 'Data jarak '!$B$2:$K$11))} -> 397.4792 | H10: =$B$3*F10*G10 -> 7.6043057e+08 | K10: P1 | L10: P1 | M10: P10 | N10: 70439.32 | P10: {=XLOOKUP(L10, 'Data jarak '!$A$2:$A$11, XLOOKUP(M10, 'Data jarak '!$B$1:$K$1, 'Data jarak '!$B$2:$K$11))} -> 2382.411 | Q10: =$B$3*$B$4*N10*P10 -> 1887923372 | S10: P1 | T10: P4 | U10: P1 | V10: 11535.68 | W10: {=XLOOKUP(T10, 'Data jarak '!$A$2:$A$11, XLOOKUP(U10, 'Data jarak '!$B$1:$K$1, 'Data jarak '!$B$2:$K$11))} -> 909.2041 | X10: =$B$3*V10*W10 -> 1.5732431e+08 | Z10: P3 | AA10: P8 | AB10: P8 | AC10: Tidak | AD10: P8 | AE10: Valid
A11: P4 | B11: 0 | D11: P4 | E11: P6 | F11: 149109.44 | G11: {=XLOOKUP(D11, 'Data jarak '!$A$2:$A$11, XLOOKUP(E11, 'Data jarak '!$B$1:$K$1, 'Data jarak '!$B$2:$K$11))} -> 525.4495 | H11: =$B$3*F11*G11 -> 1175242210 | K11: P2 | L11: P6 | M11: P8 | N11: 9718.65 | P11: {=XLOOKUP(L11, 'Data jarak '!$A$2:$A$11, XLOOKUP(M11, 'Data jarak '!$B$1:$K$1, 'Data jarak '!$B$2:$K$11))} -> 475.5078 | Q11: =$B$3*$B$4*N11*P11 -> 51989556 | S11: P1 | T11: P5 | U11: P1 | V11: 2464.44 | W11: {=XLOOKUP(T11, 'Data jarak '!$A$2:$A$11, XLOOKUP(U11, 'Data jarak '!$B$1:$K$1, 'Data jarak '!$B$2:$K$11))} -> 1187.826 | X11: =$B$3*V11*W11 -> 43909889 | Z11: P5 | AA11: P6 | AB11: P6 | AC11: Tidak | AD11: P6 | AE11: Valid
A12: P5 | B12: 0 | D12: P5 | E12: P6 | F12: 92596.28 | G12: {=XLOOKUP(D12, 'Data jarak '!$A$2:$A$11, XLOOKUP(E12, 'Data jarak '!$B$1:$K$1, 'Data jarak '!$B$2:$K$11))} -> 176.4669 | H12: =$B$3*F12*G12 -> 2.4510268e+08 | K12: P2 | L12: P6 | M12: P10 | N12: 4136.76 | P12: {=XLOOKUP(L12, 'Data jarak '!$A$2:$A$11, XLOOKUP(M12, 'Data jarak '!$B$1:$K$1, 'Data jarak '!$B$2:$K$11))} -> 1024.79 | Q12: =$B$3*$B$4*N12*P12 -> 47692241 | S12: P1 | T12: P6 | U12: P6 | V12: 7952 | W12: {=XLOOKUP(T12, 'Data jarak '!$A$2:$A$11, XLOOKUP(U12, 'Data jarak '!$B$1:$K$1, 'Data jarak '!$B$2:$K$11))} -> 0 | X12: =$B$3*V12*W12 -> 0 | Z12: P7 | AA12: P4 | AB12: P4 | AC12: Tidak | AD12: P4 | AE12: Valid
A13: P6 | B13: 1 | D13: P6 | E13: P6 | F13: 356464.08 | G13: {=XLOOKUP(D13, 'Data jarak '!$A$2:$A$11, XLOOKUP(E13, 'Data jarak '!$B$1:$K$1, 'Data jarak '!$B$2:$K$11))} -> 0 | H13: =$B$3*F13*G13 -> 0 | K13: P3 | L13: P6 | M13: P8 | N13: 5883.31 | P13: {=XLOOKUP(L13, 'Data jarak '!$A$2:$A$11, XLOOKUP(M13, 'Data jarak '!$B$1:$K$1, 'Data jarak '!$B$2:$K$11))} -> 475.5078 | Q13: =$B$3*$B$4*N13*P13 -> 31472548 | S13: P1 | T13: P7 | U13: P6 | V13: 2382.68 | W13: {=XLOOKUP(T13, 'Data jarak '!$A$2:$A$11, XLOOKUP(U13, 'Data jarak '!$B$1:$K$1, 'Data jarak '!$B$2:$K$11))} -> 356.1662 | X13: =$B$3*V13*W13 -> 12729451 | Z13: P9 | AA13: P2 | AB13: P8 | AC13: Ada | AD13: P4 | AE13: Valid
A14: P7 | B14: 0 | D14: P7 | E14: P8 | F14: 314649.32 | G14: {=XLOOKUP(D14, 'Data jarak '!$A$2:$A$11, XLOOKUP(E14, 'Data jarak '!$B$1:$K$1, 'Data jarak '!$B$2:$K$11))} -> 186.18 | H14: =$B$3*F14*G14 -> 878721156 | K14: P3 | L14: P6 | M14: P10 | N14: 2415.04 | P14: {=XLOOKUP(L14, 'Data jarak '!$A$2:$A$11, XLOOKUP(M14, 'Data jarak '!$B$1:$K$1, 'Data jarak '!$B$2:$K$11))} -> 1024.79 | Q14: =$B$3*$B$4*N14*P14 -> 27842724 | S14: P1 | T14: P8 | U14: P8 | V14: 24726.24 | W14: {=XLOOKUP(T14, 'Data jarak '!$A$2:$A$11, XLOOKUP(U14, 'Data jarak '!$B$1:$K$1, 'Data jarak '!$B$2:$K$11))} -> 0 | X14: =$B$3*V14*W14 -> 0
A15: P8 | B15: 1 | D15: P8 | E15: P8 | F15: 1366604.9 | G15: {=XLOOKUP(D15, 'Data jarak '!$A$2:$A$11, XLOOKUP(E15, 'Data jarak '!$B$1:$K$1, 'Data jarak '!$B$2:$K$11))} -> 0 | H15: =$B$3*F15*G15 -> 0 | K15: P4 | L15: P6 | M15: P8 | N15: 18203.37 | P15: {=XLOOKUP(L15, 'Data jarak '!$A$2:$A$11, XLOOKUP(M15, 'Data jarak '!$B$1:$K$1, 'Data jarak '!$B$2:$K$11))} -> 475.5078 | Q15: =$B$3*$B$4*N15*P15 -> 97378250 | S15: P1 | T15: P9 | U15: P8 | V15: 2266.6 | W15: {=XLOOKUP(T15, 'Data jarak '!$A$2:$A$11, XLOOKUP(U15, 'Data jarak '!$B$1:$K$1, 'Data jarak '!$B$2:$K$11))} -> 403.0102 | X15: =$B$3*V15*W15 -> 13701944
A16: P9 | B16: 0 | D16: P9 | E16: P8 | F16: 42730.01 | G16: {=XLOOKUP(D16, 'Data jarak '!$A$2:$A$11, XLOOKUP(E16, 'Data jarak '!$B$1:$K$1, 'Data jarak '!$B$2:$K$11))} -> 403.0102 | H16: =$B$3*F16*G16 -> 2.5830945e+08 | K16: P4 | L16: P6 | M16: P10 | N16: 12387.4 | P16: {=XLOOKUP(L16, 'Data jarak '!$A$2:$A$11, XLOOKUP(M16, 'Data jarak '!$B$1:$K$1, 'Data jarak '!$B$2:$K$11))} -> 1024.79 | Q16: =$B$3*$B$4*N16*P16 -> 142812941 | S16: P1 | T16: P10 | U16: P10 | V16: 70439.32 | W16: {=XLOOKUP(T16, 'Data jarak '!$A$2:$A$11, XLOOKUP(U16, 'Data jarak '!$B$1:$K$1, 'Data jarak '!$B$2:$K$11))} -> 0 | X16: =$B$3*V16*W16 -> 0
A17: P10 | B17: 0 | D17: P10 | E17: P8 | F17: 171260.44 | G17: {=XLOOKUP(D17, 'Data jarak '!$A$2:$A$11, XLOOKUP(E17, 'Data jarak '!$B$1:$K$1, 'Data jarak '!$B$2:$K$11))} -> 658.2451 | H17: =$B$3*F17*G17 -> 1690970182 | K17: P5 | L17: P6 | M17: P8 | N17: 21555.56 | P17: {=XLOOKUP(L17, 'Data jarak '!$A$2:$A$11, XLOOKUP(M17, 'Data jarak '!$B$1:$K$1, 'Data jarak '!$B$2:$K$11))} -> 475.5078 | Q17: =$B$3*$B$4*N17*P17 -> 1.1531067e+08 | S17: P2 | T17: P1 | U17: P1 | V17: 1517.87 | W17: {=XLOOKUP(T17, 'Data jarak '!$A$2:$A$11, XLOOKUP(U17, 'Data jarak '!$B$1:$K$1, 'Data jarak '!$B$2:$K$11))} -> 0 | X17: =$B$3*V17*W17 -> 0
A18: P11 | B18: 0 | D18: P10 | E18: P13 | F18: 190604.6 | G18: {=XLOOKUP(D18, 'Data jarak '!$A$2:$A$11, XLOOKUP(E18, 'Data jarak '!$B$1:$K$1, 'Data jarak '!$B$2:$K$11))} -> #N/A | H18: =$B$3*F18*G18 -> #N/A | K18: P5 | L18: P6 | M18: P10 | N18: 5911.52 | P18: {=XLOOKUP(L18, 'Data jarak '!$A$2:$A$11, XLOOKUP(M18, 'Data jarak '!$B$1:$K$1, 'Data jarak '!$B$2:$K$11))} -> 1024.79 | Q18: =$B$3*$B$4*N18*P18 -> 68153249 | S18: P2 | T18: P3 | U18: P6 | V18: 1940.46 | W18: {=XLOOKUP(T18, 'Data jarak '!$A$2:$A$11, XLOOKUP(U18, 'Data jarak '!$B$1:$K$1, 'Data jarak '!$B$2:$K$11))} -> 397.4792 | X18: =$B$3*V18*W18 -> 11569387
A19: P12 | B19: 0 | D19: P11 | E19: P6 | F19: 52154.96 | G19: {=XLOOKUP(D19, 'Data jarak '!$A$2:$A$11, XLOOKUP(E19, 'Data jarak '!$B$1:$K$1, 'Data jarak '!$B$2:$K$11))} -> #N/A | H19: =$B$3*F19*G19 -> #N/A | K19: P6 | L19: P6 | M19: P1 | N19: 2334.6 | P19: {=XLOOKUP(L19, 'Data jarak '!$A$2:$A$11, XLOOKUP(M19, 'Data jarak '!$B$1:$K$1, 'Data jarak '!$B$2:$K$11))} -> 1362.65 | Q19: =$B$3*$B$4*N19*P19 -> 35788980 | S19: P2 | T19: P4 | U19: P1 | V19: 4244.09 | W19: {=XLOOKUP(T19, 'Data jarak '!$A$2:$A$11, XLOOKUP(U19, 'Data jarak '!$B$1:$K$1, 'Data jarak '!$B$2:$K$11))} -> 909.2041 | X19: =$B$3*V19*W19 -> 57881160
A20: P13 | B20: 1 | D20: P12 | E20: P13 | F20: 995865.48 | G20: {=XLOOKUP(D20, 'Data jarak '!$A$2:$A$11, XLOOKUP(E20, 'Data jarak '!$B$1:$K$1, 'Data jarak '!$B$2:$K$11))} -> #N/A | H20: =$B$3*F20*G20 -> #N/A | K20: P6 | L20: P6 | M20: P8 | N20: 35521.71 | P20: {=XLOOKUP(L20, 'Data jarak '!$A$2:$A$11, XLOOKUP(M20, 'Data jarak '!$B$1:$K$1, 'Data jarak '!$B$2:$K$11))} -> 475.5078 | Q20: =$B$3*$B$4*N20*P20 -> 1.9002206e+08 | S20: P2 | T20: P5 | U20: P6 | V20: 547.44 | W20: {=XLOOKUP(T20, 'Data jarak '!$A$2:$A$11, XLOOKUP(U20, 'Data jarak '!$B$1:$K$1, 'Data jarak '!$B$2:$K$11))} -> 176.4669 | X20: =$B$3*V20*W20 -> 1449075.6
A21: P14 | B21: 0 | D21: P13 | E21: P13 | F21: 1029824.1 | G21: {=XLOOKUP(D21, 'Data jarak '!$A$2:$A$11, XLOOKUP(E21, 'Data jarak '!$B$1:$K$1, 'Data jarak '!$B$2:$K$11))} -> #N/A | H21: =$B$3*F21*G21 -> #N/A | K21: P6 | L21: P6 | M21: P10 | N21: 6665.76 | P21: {=XLOOKUP(L21, 'Data jarak '!$A$2:$A$11, XLOOKUP(M21, 'Data jarak '!$B$1:$K$1, 'Data jarak '!$B$2:$K$11))} -> 1024.79 | Q21: =$B$3*$B$4*N21*P21 -> 76848797 | S21: P2 | T21: P6 | U21: P6 | V21: 6251.74 | W21: {=XLOOKUP(T21, 'Data jarak '!$A$2:$A$11, XLOOKUP(U21, 'Data jarak '!$B$1:$K$1, 'Data jarak '!$B$2:$K$11))} -> 0 | X21: =$B$3*V21*W21 -> 0
A22: P15 | B22: 1 | D22: P14 | E22: P15 | F22: 62587.04 | G22: {=XLOOKUP(D22, 'Data jarak '!$A$2:$A$11, XLOOKUP(E22, 'Data jarak '!$B$1:$K$1, 'Data jarak '!$B$2:$K$11))} -> #N/A | H22: =$B$3*F22*G22 -> #N/A | K22: P7 | L22: P6 | M22: P1 | N22: 2873.96 | P22: {=XLOOKUP(L22, 'Data jarak '!$A$2:$A$11, XLOOKUP(M22, 'Data jarak '!$B$1:$K$1, 'Data jarak '!$B$2:$K$11))} -> 1362.65 | Q22: =$B$3*$B$4*N22*P22 -> 44057268 | S22: P2 | T22: P7 | U22: P6 | V22: 2635.73 | W22: {=XLOOKUP(T22, 'Data jarak '!$A$2:$A$11, XLOOKUP(U22, 'Data jarak '!$B$1:$K$1, 'Data jarak '!$B$2:$K$11))} -> 356.1662 | X22: =$B$3*V22*W22 -> 14081369
A23: P16 | B23: 0 | D23: P15 | E23: P15 | F23: 1162580.2 | G23: {=XLOOKUP(D23, 'Data jarak '!$A$2:$A$11, XLOOKUP(E23, 'Data jarak '!$B$1:$K$1, 'Data jarak '!$B$2:$K$11))} -> #N/A | H23: =$B$3*F23*G23 -> #N/A | K23: P7 | L23: P8 | M23: P10 | N23: 8546.4 | P23: {=XLOOKUP(L23, 'Data jarak '!$A$2:$A$11, XLOOKUP(M23, 'Data jarak '!$B$1:$K$1, 'Data jarak '!$B$2:$K$11))} -> 658.2451 | Q23: =$B$3*$B$4*N23*P23 -> 63288292 | S23: P2 | T23: P8 | U23: P8 | V23: 6039.82 | W23: {=XLOOKUP(T23, 'Data jarak '!$A$2:$A$11, XLOOKUP(U23, 'Data jarak '!$B$1:$K$1, 'Data jarak '!$B$2:$K$11))} -> 0 | X23: =$B$3*V23*W23 -> 0
A24: P17 | B24: 0 | D24: P16 | E24: P15 | F24: 134893.6 | K24: P8 | L24: P8 | M24: P1 | N24: 30724.48 | P24: {=XLOOKUP(L24, 'Data jarak '!$A$2:$A$11, XLOOKUP(M24, 'Data jarak '!$B$1:$K$1, 'Data jarak '!$B$2:$K$11))} -> 1810.495 | Q24: =$B$3*$B$4*N24*P24 -> 6.2579832e+08 | S24: P2 | T24: P9 | U24: P8 | V24: 3678.83 | W24: {=XLOOKUP(T24, 'Data jarak '!$A$2:$A$11, XLOOKUP(U24, 'Data jarak '!$B$1:$K$1, 'Data jarak '!$B$2:$K$11))} -> 403.0102 | X24: =$B$3*V24*W24 -> 22239090
A25: P18 | B25: 0 | D25: P17 | E25: P13 | F25: 490447.52 | K25: P8 | L25: P8 | M25: P6 | N25: 248498.7 | P25: {=XLOOKUP(L25, 'Data jarak '!$A$2:$A$11, XLOOKUP(M25, 'Data jarak '!$B$1:$K$1, 'Data jarak '!$B$2:$K$11))} -> 475.5078 | Q25: =$B$3*$B$4*N25*P25 -> 1329334539 | S25: P2 | T25: P10 | U25: P10 | V25: 4136.76 | W25: {=XLOOKUP(T25, 'Data jarak '!$A$2:$A$11, XLOOKUP(U25, 'Data jarak '!$B$1:$K$1, 'Data jarak '!$B$2:$K$11))} -> 0 | X25: =$B$3*V25*W25 -> 0
A26: P19 | B26: 0 | D26: P17 | E26: P15 | F26: 319277.12 | K26: P8 | L26: P8 | M26: P10 | N26: 101245.44 | P26: {=XLOOKUP(L26, 'Data jarak '!$A$2:$A$11, XLOOKUP(M26, 'Data jarak '!$B$1:$K$1, 'Data jarak '!$B$2:$K$11))} -> 658.2451 | Q26: =$B$3*$B$4*N26*P26 -> 7.4974854e+08 | S26: P3 | T26: P1 | U26: P1 | V26: 881.92 | W26: {=XLOOKUP(T26, 'Data jarak '!$A$2:$A$11, XLOOKUP(U26, 'Data jarak '!$B$1:$K$1, 'Data jarak '!$B$2:$K$11))} -> 0 | X26: =$B$3*V26*W26 -> 0
A27: P20 | B27: 0 | D27: P18 | E27: P15 | F27: 43691.6 | K27: P9 | L27: P8 | M27: P1 | N27: 535.69 | P27: {=XLOOKUP(L27, 'Data jarak '!$A$2:$A$11, XLOOKUP(M27, 'Data jarak '!$B$1:$K$1, 'Data jarak '!$B$2:$K$11))} -> 1810.495 | Q27: =$B$3*$B$4*N27*P27 -> 10910971 | S27: P3 | T27: P2 | U27: P6 | V27: 768.89 | W27: {=XLOOKUP(T27, 'Data jarak '!$A$2:$A$11, XLOOKUP(U27, 'Data jarak '!$B$1:$K$1, 'Data jarak '!$B$2:$K$11))} -> 966.6815 | X27: =$B$3*V27*W27 -> 11149076
A28: P21 | B28: 0 | D28: P19 | E28: P15 | F28: 149835.36 | K28: P9 | L28: P8 | M28: P6 | N28: 6615.99 | P28: {=XLOOKUP(L28, 'Data jarak '!$A$2:$A$11, XLOOKUP(M28, 'Data jarak '!$B$1:$K$1, 'Data jarak '!$B$2:$K$11))} -> 475.5078 | Q28: =$B$3*$B$4*N28*P28 -> 35391992 | S28: P3 | T28: P4 | U28: P6 | V28: 2095.4 | W28: {=XLOOKUP(T28, 'Data jarak '!$A$2:$A$11, XLOOKUP(U28, 'Data jarak '!$B$1:$K$1, 'Data jarak '!$B$2:$K$11))} -> 525.4495 | X28: =$B$3*V28*W28 -> 16515403
A29: P22 | B29: 0 | D29: P20 | E29: P13 | F29: 226389.56 | K29: P10 | L29: P10 | M29: P1 | N29: 29981.56 | P29: {=XLOOKUP(L29, 'Data jarak '!$A$2:$A$11, XLOOKUP(M29, 'Data jarak '!$B$1:$K$1, 'Data jarak '!$B$2:$K$11))} -> 2382.411 | Q29: =$B$3*$B$4*N29*P29 -> 8.0356948e+08 | S29: P3 | T29: P5 | U29: P6 | V29: 575.8 | W29: {=XLOOKUP(T29, 'Data jarak '!$A$2:$A$11, XLOOKUP(U29, 'Data jarak '!$B$1:$K$1, 'Data jarak '!$B$2:$K$11))} -> 176.4669 | X29: =$B$3*V29*W29 -> 1524144.6
A30: P23 | B30: 0 | D30: P20 | E30: P15 | F30: 125980.08 | K30: P10 | L30: P10 | M30: P6 | N30: 65423.14 | P30: {=XLOOKUP(L30, 'Data jarak '!$A$2:$A$11, XLOOKUP(M30, 'Data jarak '!$B$1:$K$1, 'Data jarak '!$B$2:$K$11))} -> 1024.79 | Q30: =$B$3*$B$4*N30*P30 -> 754256021 | S30: P3 | T30: P6 | U30: P6 | V30: 4265.72 | W30: {=XLOOKUP(T30, 'Data jarak '!$A$2:$A$11, XLOOKUP(U30, 'Data jarak '!$B$1:$K$1, 'Data jarak '!$B$2:$K$11))} -> 0 | X30: =$B$3*V30*W30 -> 0
A31: P24 | B31: 0 | D31: P21 | E31: P15 | F31: 190537.16 | K31: P10 | L31: P10 | M31: P8 | N31: 56329.16 | P31: {=XLOOKUP(L31, 'Data jarak '!$A$2:$A$11, XLOOKUP(M31, 'Data jarak '!$B$1:$K$1, 'Data jarak '!$B$2:$K$11))} -> 658.2451 | Q31: =$B$3*$B$4*N31*P31 -> 4.1713193e+08 | S31: P3 | T31: P7 | U31: P6 | V31: 10479.28 | W31: {=XLOOKUP(T31, 'Data jarak '!$A$2:$A$11, XLOOKUP(U31, 'Data jarak '!$B$1:$K$1, 'Data jarak '!$B$2:$K$11))} -> 356.1662 | X31: =$B$3*V31*W31 -> 55985480
D32: P22 | E32: P15 | F32: 221085.64 | S32: P3 | T32: P8 | U32: P8 | V32: 5041.36 | W32: {=XLOOKUP(T32, 'Data jarak '!$A$2:$A$11, XLOOKUP(U32, 'Data jarak '!$B$1:$K$1, 'Data jarak '!$B$2:$K$11))} -> 0 | X32: =$B$3*V32*W32 -> 0
D33: P23 | E33: P15 | F33: 38461.84 | S33: P3 | T33: P9 | U33: P8 | V33: 841.95 | W33: {=XLOOKUP(T33, 'Data jarak '!$A$2:$A$11, XLOOKUP(U33, 'Data jarak '!$B$1:$K$1, 'Data jarak '!$B$2:$K$11))} -> 403.0102 | X33: =$B$3*V33*W33 -> 5089716.6
D34: P24 | E34: P15 | F34: 151429.12 | S34: P3 | T34: P10 | U34: P10 | V34: 2415.04 | W34: {=XLOOKUP(T34, 'Data jarak '!$A$2:$A$11, XLOOKUP(U34, 'Data jarak '!$B$1:$K$1, 'Data jarak '!$B$2:$K$11))} -> 0 | X34: =$B$3*V34*W34 -> 0
S35: P4 | T35: P1 | U35: P1 | V35: 2877.88 | W35: {=XLOOKUP(T35, 'Data jarak '!$A$2:$A$11, XLOOKUP(U35, 'Data jarak '!$B$1:$K$1, 'Data jarak '!$B$2:$K$11))} -> 0 | X35: =$B$3*V35*W35 -> 0
S36: P4 | T36: P2 | U36: P1 | V36: 2837.35 | W36: {=XLOOKUP(T36, 'Data jarak '!$A$2:$A$11, XLOOKUP(U36, 'Data jarak '!$B$1:$K$1, 'Data jarak '!$B$2:$K$11))} -> 404.8972 | X36: =$B$3*V36*W36 -> 17232526
S37: P4 | T37: P3 | U37: P6 | V37: 2340.64 | W37: {=XLOOKUP(T37, 'Data jarak '!$A$2:$A$11, XLOOKUP(U37, 'Data jarak '!$B$1:$K$1, 'Data jarak '!$B$2:$K$11))} -> 397.4792 | X37: =$B$3*V37*W37 -> 13955336
S38: P4 | T38: P5 | U38: P6 | V38: 1346.84 | W38: {=XLOOKUP(T38, 'Data jarak '!$A$2:$A$11, XLOOKUP(U38, 'Data jarak '!$B$1:$K$1, 'Data jarak '!$B$2:$K$11))} -> 176.4669 | X38: =$B$3*V38*W38 -> 3565090.2
S39: P4 | T39: P6 | U39: P6 | V39: 7897.68 | W39: {=XLOOKUP(T39, 'Data jarak '!$A$2:$A$11, XLOOKUP(U39, 'Data jarak '!$B$1:$K$1, 'Data jarak '!$B$2:$K$11))} -> 0 | X39: =$B$3*V39*W39 -> 0
S40: P4 | T40: P7 | U40: P6 | V40: 3023.8 | W40: {=XLOOKUP(T40, 'Data jarak '!$A$2:$A$11, XLOOKUP(U40, 'Data jarak '!$B$1:$K$1, 'Data jarak '!$B$2:$K$11))} -> 356.1662 | X40: =$B$3*V40*W40 -> 16154630
S41: P4 | T41: P8 | U41: P8 | V41: 15699.2 | W41: {=XLOOKUP(T41, 'Data jarak '!$A$2:$A$11, XLOOKUP(U41, 'Data jarak '!$B$1:$K$1, 'Data jarak '!$B$2:$K$11))} -> 0 | X41: =$B$3*V41*W41 -> 0
...

Sheet Incomplete_SA
G1: Obj 1 | H1: Obj 2 | I1: Obj 3 | L1: Cplex
F2: Objective Function | G2: =sum(I13:I22) -> 2533499895 | H2: =sum(K13:K22) -> 1997257673 | I2: =sum(S13:S42) -> 8256800106 | J2: =sum(G2:I2) -> 12787557674 | L2: 12787558415 | N2: =J2-L2 -> -741.05646
D3: Cs | E3: 15 | J3: Valid
D4: Alpha | E4: 0.75
A11: Hub | D11: Assignment | M11: Yikm
A12: Node | B12: is_hub | D12: Origin | E12: Hub | F12: Value | G12: Dist | H12: Oi | I12: Obj1 | J12: Di | K12: obj2 | M12: Origin | N12: Hub1 | O12: Hub2 | P12: Flow | Q12: Validate Flow | R12: Dist
A13: P1 | B13: 0 | D13: P1 | E13: P4 | F13: 1 | G13: {=XLOOKUP(D13, 'Data jarak '!$A$2:$A$11, XLOOKUP(E13, 'Data jarak '!$B$1:$K$1, 'Data jarak '!$B$2:$K$11))} -> 909.2041 | H13: =vlookup(D13, Sheet4!$G$1:$I$11,2,0) -> 125092.16 | I13: =H13*G13*$E$3 -> 1706014571 | J13: =vlookup(D13, Sheet4!$G$1:$I$11,3,0) -> 73644.52 | K13: =J13*G13*$E$3 -> 1004368493 | M13: P1 | N13: P4 | O13: P6 | P13: 12280.84 | R13: {=XLOOKUP(N13, 'Data jarak '!$A$2:$A$11, XLOOKUP(O13, 'Data jarak '!$B$1:$K$1, 'Data jarak '!$B$2:$K$11))} -> 525.4495 | S13: =R13*P13*$E$3*$E$4 -> 72595814
A14: P2 | B14: 0 | D14: P2 | E14: P4 | F14: 1 | G14: {=XLOOKUP(D14, 'Data jarak '!$A$2:$A$11, XLOOKUP(E14, 'Data jarak '!$B$1:$K$1, 'Data jarak '!$B$2:$K$11))} -> 563.3406 | H14: =vlookup(D14, Sheet4!$G$1:$I$11,2,0) -> 30992.74 | I14: =H14*G14*$E$3 -> 2.6189203e+08 | J14: =vlookup(D14, Sheet4!$G$1:$I$11,3,0) -> 21308.78 | K14: =J14*G14*$E$3 -> 1.8006151e+08 | M14: P1 | N14: P4 | O14: P8 | P14: 29375.52 | R14: {=XLOOKUP(N14, 'Data jarak '!$A$2:$A$11, XLOOKUP(O14, 'Data jarak '!$B$1:$K$1, 'Data jarak '!$B$2:$K$11))} -> 918.1315 | S14: =R14*P14*$E$3*$E$4 -> 3.0341914e+08
A15: P3 | B15: 0 | D15: P3 | E15: P6 | F15: 1 | G15: {=XLOOKUP(D15, 'Data jarak '!$A$2:$A$11, XLOOKUP(E15, 'Data jarak '!$B$1:$K$1, 'Data jarak '!$B$2:$K$11))} -> 397.4792 | H15: =vlookup(D15, Sheet4!$G$1:$I$11,2,0) -> 27365.36 | I15: =H15*G15*$E$3 -> 163157421 | J15: =vlookup(D15, Sheet4!$G$1:$I$11,3,0) -> 48760.24 | K15: =J15*G15*$E$3 -> 2.9071772e+08 | M15: P1 | N15: P4 | O15: P10 | P15: 70439.32 | R15: {=XLOOKUP(N15, 'Data jarak '!$A$2:$A$11, XLOOKUP(O15, 'Data jarak '!$B$1:$K$1, 'Data jarak '!$B$2:$K$11))} -> 1535.299 | S15: =R15*P15*$E$3*$E$4 -> 1216635948
A16: P4 | B16: 1 | D16: P4 | E16: P4 | F16: 1 | G16: {=XLOOKUP(D16, 'Data jarak '!$A$2:$A$11, XLOOKUP(E16, 'Data jarak '!$B$1:$K$1, 'Data jarak '!$B$2:$K$11))} -> 0 | H16: =vlookup(D16, Sheet4!$G$1:$I$11,2,0) -> 50914.96 | I16: =H16*G16*$E$3 -> 0 | J16: =vlookup(D16, Sheet4!$G$1:$I$11,3,0) -> 147517.64 | K16: =J16*G16*$E$3 -> 0 | M16: P2 | N16: P4 | O16: P6 | P16: 8739.64 | R16: {=XLOOKUP(N16, 'Data jarak '!$A$2:$A$11, XLOOKUP(O16, 'Data jarak '!$B$1:$K$1, 'Data jarak '!$B$2:$K$11))} -> 525.4495 | S16: =R16*P16*$E$3*$E$4 -> 51662694
A17: P5 | B17: 0 | D17: P5 | E17: P6 | F17: 1 | G17: {=XLOOKUP(D17, 'Data jarak '!$A$2:$A$11, XLOOKUP(E17, 'Data jarak '!$B$1:$K$1, 'Data jarak '!$B$2:$K$11))} -> 176.4669 | H17: =vlookup(D17, Sheet4!$G$1:$I$11,2,0) -> 40906.08 | I17: =H17*G17*$E$3 -> 1.0827854e+08 | J17: =vlookup(D17, Sheet4!$G$1:$I$11,3,0) -> 49314.56 | K17: =J17*G17*$E$3 -> 1.3053581e+08 | M17: P2 | N17: P4 | O17: P8 | P17: 12354.38 | R17: {=XLOOKUP(N17, 'Data jarak '!$A$2:$A$11, XLOOKUP(O17, 'Data jarak '!$B$1:$K$1, 'Data jarak '!$B$2:$K$11))} -> 918.1315 | S17: =R17*P17*$E$3*$E$4 -> 1.2760814e+08
A18: P6 | B18: 1 | D18: P6 | E18: P6 | F18: 1 | G18: {=XLOOKUP(D18, 'Data jarak '!$A$2:$A$11, XLOOKUP(E18, 'Data jarak '!$B$1:$K$1, 'Data jarak '!$B$2:$K$11))} -> 0 | H18: =vlookup(D18, Sheet4!$G$1:$I$11,2,0) -> 64470.2 | I18: =H18*G18*$E$3 -> 0 | J18: =vlookup(D18, Sheet4!$G$1:$I$11,3,0) -> 187313.74 | K18: =J18*G18*$E$3 -> 0 | M18: P2 | N18: P4 | O18: P10 | P18: 4136.76 | R18: {=XLOOKUP(N18, 'Data jarak '!$A$2:$A$11, XLOOKUP(O18, 'Data jarak '!$B$1:$K$1, 'Data jarak '!$B$2:$K$11))} -> 1535.299 | S18: =R18*P18*$E$3*$E$4 -> 71450589
A19: P7 | B19: 0 | D19: P7 | E19: P8 | F19: 1 | G19: {=XLOOKUP(D19, 'Data jarak '!$A$2:$A$11, XLOOKUP(E19, 'Data jarak '!$B$1:$K$1, 'Data jarak '!$B$2:$K$11))} -> 186.18 | H19: =vlookup(D19, Sheet4!$G$1:$I$11,2,0) -> 75267.84 | I19: =H19*G19*$E$3 -> 2.102005e+08 | J19: =vlookup(D19, Sheet4!$G$1:$I$11,3,0) -> 44041.76 | K19: =J19*G19*$E$3 -> 1.2299542e+08 | M19: P3 | N19: P6 | O19: P4 | P19: 3746.21 | R19: {=XLOOKUP(N19, 'Data jarak '!$A$2:$A$11, XLOOKUP(O19, 'Data jarak '!$B$1:$K$1, 'Data jarak '!$B$2:$K$11))} -> 525.4495 | S19: =R19*P19*$E$3*$E$4 -> 22144997
A20: P8 | B20: 1 | D20: P8 | E20: P8 | F20: 1 | G20: {=XLOOKUP(D20, 'Data jarak '!$A$2:$A$11, XLOOKUP(E20, 'Data jarak '!$B$1:$K$1, 'Data jarak '!$B$2:$K$11))} -> 0 | H20: =vlookup(D20, Sheet4!$G$1:$I$11,2,0) -> 420950.02 | I20: =H20*G20*$E$3 -> 0 | J20: =vlookup(D20, Sheet4!$G$1:$I$11,3,0) -> 176319.88 | K20: =J20*G20*$E$3 -> 0 | M20: P3 | N20: P6 | O20: P8 | P20: 16362.59 | R20: {=XLOOKUP(N20, 'Data jarak '!$A$2:$A$11, XLOOKUP(O20, 'Data jarak '!$B$1:$K$1, 'Data jarak '!$B$2:$K$11))} -> 475.5078 | S20: =R20*P20*$E$3*$E$4 -> 87531066
A21: P9 | B21: 0 | D21: P9 | E21: P8 | F21: 1 | G21: {=XLOOKUP(D21, 'Data jarak '!$A$2:$A$11, XLOOKUP(E21, 'Data jarak '!$B$1:$K$1, 'Data jarak '!$B$2:$K$11))} -> 403.0102 | H21: =vlookup(D21, Sheet4!$G$1:$I$11,2,0) -> 13888.29 | I21: =H21*G21*$E$3 -> 83956838 | J21: =vlookup(D21, Sheet4!$G$1:$I$11,3,0) -> 44428.77 | K21: =J21*G21*$E$3 -> 2.6857871e+08 | M21: P3 | N21: P6 | O21: P10 | P21: 2415.04 | R21: {=XLOOKUP(N21, 'Data jarak '!$A$2:$A$11, XLOOKUP(O21, 'Data jarak '!$B$1:$K$1, 'Data jarak '!$B$2:$K$11))} -> 1024.79 | S21: =R21*P21*$E$3*$E$4 -> 27842724
A22: P10 | B22: 1 | D22: P10 | E22: P10 | F22: 1 | G22: {=XLOOKUP(D22, 'Data jarak '!$A$2:$A$11, XLOOKUP(E22, 'Data jarak '!$B$1:$K$1, 'Data jarak '!$B$2:$K$11))} -> 0 | H22: =vlookup(D22, Sheet4!$G$1:$I$11,2,0) -> 156335.24 | I22: =H22*G22*$E$3 -> 0 | J22: =vlookup(D22, Sheet4!$G$1:$I$11,3,0) -> 213533 | K22: =J22*G22*$E$3 -> 0 | M22: P4 | N22: P4 | O22: P6 | P22: 11585.16 | R22: {=XLOOKUP(N22, 'Data jarak '!$A$2:$A$11, XLOOKUP(O22, 'Data jarak '!$B$1:$K$1, 'Data jarak '!$B$2:$K$11))} -> 525.4495 | S22: =R22*P22*$E$3*$E$4 -> 68483436
M23: P4 | N23: P4 | O23: P8 | P23: 21227.17 | R23: {=XLOOKUP(N23, 'Data jarak '!$A$2:$A$11, XLOOKUP(O23, 'Data jarak '!$B$1:$K$1, 'Data jarak '!$B$2:$K$11))} -> 918.1315 | S23: =R23*P23*$E$3*$E$4 -> 2.19255e+08
M24: P4 | N24: P4 | O24: P10 | P24: 12387.4 | R24: {=XLOOKUP(N24, 'Data jarak '!$A$2:$A$11, XLOOKUP(O24, 'Data jarak '!$B$1:$K$1, 'Data jarak '!$B$2:$K$11))} -> 1535.299 | S24: =R24*P24*$E$3*$E$4 -> 2.1395658e+08
A25: Validasi Routing | M25: P5 | N25: P6 | O25: P4 | P25: 6239.84 | R25: {=XLOOKUP(N25, 'Data jarak '!$A$2:$A$11, XLOOKUP(O25, 'Data jarak '!$B$1:$K$1, 'Data jarak '!$B$2:$K$11))} -> 525.4495 | S25: =R25*P25*$E$3*$E$4 -> 36885609
A26: Pelabuhan Asal | B26: Pelabuhan Tujuan | C26: Hub Awal | D26: Antar Hub | E26: Hub Akhir | F26: Status | M26: P5 | N26: P6 | O26: P8 | P26: 22533.08 | R26: {=XLOOKUP(N26, 'Data jarak '!$A$2:$A$11, XLOOKUP(O26, 'Data jarak '!$B$1:$K$1, 'Data jarak '!$B$2:$K$11))} -> 475.5078 | S26: =R26*P26*$E$3*$E$4 -> 1.2053987e+08
A27: P1 | B27: P10 | C27: P4 | D27: Ada | E27: P8 | F27: Valid | M27: P5 | N27: P6 | O27: P10 | P27: 5911.52 | R27: {=XLOOKUP(N27, 'Data jarak '!$A$2:$A$11, XLOOKUP(O27, 'Data jarak '!$B$1:$K$1, 'Data jarak '!$B$2:$K$11))} -> 1024.79 | S27: =R27*P27*$E$3*$E$4 -> 68153249
A28: P3 | B28: P8 | C28: P6 | D28: Ada | E28: P8 | F28: Valid | M28: P6 | N28: P6 | O28: P4 | P28: 14860.53 | R28: {=XLOOKUP(N28, 'Data jarak '!$A$2:$A$11, XLOOKUP(O28, 'Data jarak '!$B$1:$K$1, 'Data jarak '!$B$2:$K$11))} -> 525.4495 | S28: =R28*P28*$E$3*$E$4 -> 87845153
A29: P5 | B29: P6 | C29: P6 | D29: Ada | E29: P6 | F29: Valid | M29: P6 | N29: P6 | O29: P8 | P29: 38057.03 | R29: {=XLOOKUP(N29, 'Data jarak '!$A$2:$A$11, XLOOKUP(O29, 'Data jarak '!$B$1:$K$1, 'Data jarak '!$B$2:$K$11))} -> 475.5078 | S29: =R29*P29*$E$3*$E$4 -> 2.0358466e+08
A30: P7 | B30: P4 | C30: P8 | D30: Ada | E30: P4 | F30: Valid | M30: P6 | N30: P6 | O30: P10 | P30: 6665.76 | R30: {=XLOOKUP(N30, 'Data jarak '!$A$2:$A$11, XLOOKUP(O30, 'Data jarak '!$B$1:$K$1, 'Data jarak '!$B$2:$K$11))} -> 1024.79 | S30: =R30*P30*$E$3*$E$4 -> 76848797
A31: P9 | B31: P2 | C31: P8 | D31: Ada | E31: P4 | F31: Valid | M31: P7 | N31: P8 | O31: P4 | P31: 12683.13 | R31: {=XLOOKUP(N31, 'Data jarak '!$A$2:$A$11, XLOOKUP(O31, 'Data jarak '!$B$1:$K$1, 'Data jarak '!$B$2:$K$11))} -> 918.1315 | S31: =R31*P31*$E$3*$E$4 -> 1.3100379e+08
M32: P7 | N32: P8 | O32: P6 | P32: 35520.88 | R32: {=XLOOKUP(N32, 'Data jarak '!$A$2:$A$11, XLOOKUP(O32, 'Data jarak '!$B$1:$K$1, 'Data jarak '!$B$2:$K$11))} -> 475.5078 | S32: =R32*P32*$E$3*$E$4 -> 1.9001762e+08
M33: P7 | N33: P8 | O33: P10 | P33: 8546.4 | R33: {=XLOOKUP(N33, 'Data jarak '!$A$2:$A$11, XLOOKUP(O33, 'Data jarak '!$B$1:$K$1, 'Data jarak '!$B$2:$K$11))} -> 658.2451 | S33: =R33*P33*$E$3*$E$4 -> 63288292
M34: P8 | N34: P8 | O34: P4 | P34: 109854.74 | R34: {=XLOOKUP(N34, 'Data jarak '!$A$2:$A$11, XLOOKUP(O34, 'Data jarak '!$B$1:$K$1, 'Data jarak '!$B$2:$K$11))} -> 918.1315 | S34: =R34*P34*$E$3*$E$4 -> 1134687344
M35: P8 | N35: P8 | O35: P6 | P35: 169368.44 | R35: {=XLOOKUP(N35, 'Data jarak '!$A$2:$A$11, XLOOKUP(O35, 'Data jarak '!$B$1:$K$1, 'Data jarak '!$B$2:$K$11))} -> 475.5078 | S35: =R35*P35*$E$3*$E$4 -> 9.0603016e+08
M36: P8 | N36: P8 | O36: P10 | P36: 101245.44 | R36: {=XLOOKUP(N36, 'Data jarak '!$A$2:$A$11, XLOOKUP(O36, 'Data jarak '!$B$1:$K$1, 'Data jarak '!$B$2:$K$11))} -> 658.2451 | S36: =R36*P36*$E$3*$E$4 -> 7.4974854e+08
M37: P9 | N37: P8 | O37: P4 | P37: 3351.92 | R37: {=XLOOKUP(N37, 'Data jarak '!$A$2:$A$11, XLOOKUP(O37, 'Data jarak '!$B$1:$K$1, 'Data jarak '!$B$2:$K$11))} -> 918.1315 | S37: =R37*P37*$E$3*$E$4 -> 34621913
M38: P9 | N38: P8 | O38: P6 | P38: 3799.76 | R38: {=XLOOKUP(N38, 'Data jarak '!$A$2:$A$11, XLOOKUP(O38, 'Data jarak '!$B$1:$K$1, 'Data jarak '!$B$2:$K$11))} -> 475.5078 | S38: =R38*P38*$E$3*$E$4 -> 20326675
M39: P9 | N39: P8 | O39: P10 | P39: 1785.4 | R39: {=XLOOKUP(N39, 'Data jarak '!$A$2:$A$11, XLOOKUP(O39, 'Data jarak '!$B$1:$K$1, 'Data jarak '!$B$2:$K$11))} -> 658.2451 | S39: =R39*P39*$E$3*$E$4 -> 13221347
M40: P10 | N40: P10 | O40: P4 | P40: 67260.9 | R40: {=XLOOKUP(N40, 'Data jarak '!$A$2:$A$11, XLOOKUP(O40, 'Data jarak '!$B$1:$K$1, 'Data jarak '!$B$2:$K$11))} -> 1535.299 | S40: =R40*P40*$E$3*$E$4 -> 1161737916
M41: P10 | N41: P10 | O41: P6 | P41: 28143.8 | R41: {=XLOOKUP(N41, 'Data jarak '!$A$2:$A$11, XLOOKUP(O41, 'Data jarak '!$B$1:$K$1, 'Data jarak '!$B$2:$K$11))} -> 1024.79 | S41: =R41*P41*$E$3*$E$4 -> 324466704
M42: P10 | N42: P10 | O42: P8 | P42: 60930.54 | R42: {=XLOOKUP(N42, 'Data jarak '!$A$2:$A$11, XLOOKUP(O42, 'Data jarak '!$B$1:$K$1, 'Data jarak '!$B$2:$K$11))} -> 658.2451 | S42: =R42*P42*$E$3*$E$4 -> 4.5120633e+08

Sheet Incomplete_MA
F1: Obj 1 | G1: Obj 2 | H1: Obj 3 | I1: Total | K1: Cplex | P1: Validasi Routing
C2: Objective Function | F2: =sum(V12:V89) -> 3960470952 | G2: =sum(AD12:AD65) -> 4420371640 | H2: =sum(AP12:AP117) -> 6929785222 | I2: =sum(F2:H2) -> 15310627814 | K2: 15310629059 | M2: =I2-K2 -> -1244.5458 | P2: Pelabuhan Asal | Q2: Pelabuhan Tujuan | R2: Hub Awal | S2: Antar Hub | T2: Hub Akhir | U2: Status
A3: Cs | B3: 15 | P3: P1 | Q3: P10 | R3: P5 | S3: Ada | T3: P9 | U3: Valid
A4: Alpha | B4: 0.75 | P4: P3 | Q4: P8 | R4: P6 | S4: Tidak | T4: P7 | U4: Valid
P5: P5 | Q5: P6 | R5: P4 | S5: Tidak | T5: P4 | U5: Valid
P6: P7 | Q6: P4 | R6: P4 | S6: Tidak | T6: P4 | U6: Valid
P7: P9 | Q7: P2 | R7: P8 | S7: Ada | T7: P4 | U7: Valid
D10: Wij | H10: Eij | P10: Aijk | X10: Bijk | AF10: Ykm | AJ10: Xijkl
A11: Node | B11: is_hub | D11: Pelabuhan A | E11: Pelabuhan T | F11: Flow Teus | H11: Origin | I11: Destination | J11: Value | K11: Dist | L11: Flow | M11: Cost | P11: Origin | Q11: Destination | R11: Hub | S11: Value | T11: Dist | U11: Flow | V11: Cost | X11: Origin | Y11: Destination | Z11: Hub | AA11: Value | AB11: Dist | AC11: Flow | AD11: Cost | AF11: Hub_1 | AG11: Hub_2 | AH11: y_km | AJ11: Origin | AK11: Destination | AL11: Hub1 | AM11: Hub2 | AN11: Dist | AO11: Flow | AP11: Cost
A12: P1 | B12: 0 | D12: P1 | E12: P1 | F12: 0 | H12: P1 | I12: P4 | J12: 1 | K12: {=XLOOKUP(H12, 'Data jarak '!$A$2:$A$11, XLOOKUP(I12, 'Data jarak '!$B$1:$K$1, 'Data jarak '!$B$2:$K$11))} -> 909.2041 | L12: {=XLOOKUP(H12&I12, Sheet4!$A:$A&Sheet4!$B:$B, Sheet4!$D:$D)} -> 11535.68 | M12: =$B$3*J12*K12*L12 -> 1.5732431e+08 | P12: P1 | Q12: P2 | R12: P5 | S12: 1 | T12: {=XLOOKUP(P12, 'Data jarak '!$A$2:$A$11, XLOOKUP(R12, 'Data jarak '!$B$1:$K$1, 'Data jarak '!$B$2:$K$11))} -> 1187.826 | U12: {=XLOOKUP(P12&Q12, Sheet4!$A:$A&Sheet4!$B:$B, Sheet4!$D:$D)} -> 1460.8 | V12: =$B$3*S12*T12*U12 -> 26027643 | X12: P1 | Y12: P2 | Z12: P5 | AA12: 1 | AB12: {=XLOOKUP(Y12, 'Data jarak '!$A$2:$A$11, XLOOKUP(Z12, 'Data jarak '!$B$1:$K$1, 'Data jarak '!$B$2:$K$11))} -> 790.5225 | AC12: {=XLOOKUP(X12&Y12, Sheet4!$A:$A&Sheet4!$B:$B, Sheet4!$D:$D)} -> 1460.8 | AD12: =$B$3*AA12*AB12*AC12 -> 17321929 | AF12: P4 | AG12: P6 | AH12: 1 | AJ12: P1 | AK12: P5 | AL12: P5 | AM12: P8 | AN12: {=XLOOKUP(AL12, 'Data jarak '!$A$2:$A$11, XLOOKUP(AM12, 'Data jarak '!$B$1:$K$1, 'Data jarak '!$B$2:$K$11))} -> 647.3369 | AO12: {=XLOOKUP(AJ12&AK12, Sheet4!$A:$A&Sheet4!$B:$B, Sheet4!$D:$D)} -> 2464.44 | AP12: =$B$3*$B$4*AN12*AO12 -> 17947383
A13: P2 | B13: 0 | D13: P1 | E13: P2 | F13: 1460.8 | H13: P2 | I13: P4 | J13: 1 | K13: {=XLOOKUP(H13, 'Data jarak '!$A$2:$A$11, XLOOKUP(I13, 'Data jarak '!$B$1:$K$1, 'Data jarak '!$B$2:$K$11))} -> 563.3406 | L13: {=XLOOKUP(H13&I13, Sheet4!$A:$A&Sheet4!$B:$B, Sheet4!$D:$D)} -> 4244.08 | M13: =$B$3*J13*K13*L13 -> 35862939 | P13: P1 | Q13: P3 | R13: P5 | S13: 1 | T13: {=XLOOKUP(P13, 'Data jarak '!$A$2:$A$11, XLOOKUP(R13, 'Data jarak '!$B$1:$K$1, 'Data jarak '!$B$2:$K$11))} -> 1187.826 | U13: {=XLOOKUP(P13&Q13, Sheet4!$A:$A&Sheet4!$B:$B, Sheet4!$D:$D)} -> 1864.4 | V13: =$B$3*S13*T13*U13 -> 33218742 | X13: P1 | Y13: P3 | Z13: P5 | AA13: 1 | AB13: {=XLOOKUP(Y13, 'Data jarak '!$A$2:$A$11, XLOOKUP(Z13, 'Data jarak '!$B$1:$K$1, 'Data jarak '!$B$2:$K$11))} -> 254.9509 | AC13: {=XLOOKUP(X13&Y13, Sheet4!$A:$A&Sheet4!$B:$B, Sheet4!$D:$D)} -> 1864.4 | AD13: =$B$3*AA13*AB13*AC13 -> 7129956.9 | AF13: P4 | AG13: P8 | AH13: 1 | AJ13: P1 | AK13: P5 | AL13: P7 | AM13: P5 | AN13: {=XLOOKUP(AL13, 'Data jarak '!$A$2:$A$11, XLOOKUP(AM13, 'Data jarak '!$B$1:$K$1, 'Data jarak '!$B$2:$K$11))} -> 510.3344 | AO13: {=XLOOKUP(AJ13&AK13, Sheet4!$A:$A&Sheet4!$B:$B, Sheet4!$D:$D)} -> 2464.44 | AP13: =$B$3*$B$4*AN13*AO13 -> 14148996
